2017-04-01 23:47:00 - INFO - views:login:350 - User anshul successfully authenticated
2017-04-01 23:49:05 - INFO - views:login:350 - User anshul successfully authenticated
2017-04-01 23:51:24 - INFO - views:login:350 - User anshul successfully authenticated
2017-04-02 00:09:56 - INFO - views:login:350 - User anshul successfully authenticated
2017-04-02 03:24:47 - INFO - views:login:350 - User anshul successfully authenticated
2017-04-02 17:02:48 - INFO - views:login:350 - User anshul successfully authenticated
2017-04-02 17:03:09 - INFO - views:logout:372 - User anshul successfully logged out
2017-04-02 17:03:25 - INFO - views:login:350 - User divyesh successfully authenticated
2017-04-03 00:09:31 - INFO - views:logout:372 - User divyesh successfully logged out
2017-04-03 00:09:39 - INFO - views:login:350 - User ranjana successfully authenticated
2017-04-03 01:05:00 - INFO - views:logout:372 - User ranjana successfully logged out
2017-04-03 01:05:05 - INFO - views:login:350 - User anshul successfully authenticated
2017-04-03 01:06:06 - INFO - views:logout:372 - User anshul successfully logged out
2017-04-03 01:06:11 - INFO - views:login:350 - User ranjana successfully authenticated
2017-04-03 18:00:46 - INFO - views:login:350 - User anshul successfully authenticated
2017-04-03 18:01:49 - INFO - views:logout:372 - User anshul successfully logged out
2017-04-03 18:01:56 - INFO - views:login:350 - User ranjana successfully authenticated
2017-04-03 18:02:11 - INFO - guide_views:guide_evaluate_unevaluated_abstract:86 - SHANU
2017-04-03 18:02:14 - INFO - views:logout:372 - User ranjana successfully logged out
2017-04-03 18:02:23 - INFO - views:login:350 - User anshul successfully authenticated
2017-04-03 18:10:38 - ERROR - base:handle_uncaught_exception:284 - Internal Server Error: /user/notifications/
Traceback (most recent call last):
  File "E:\Education\GitHub Projects\PhDPortal\env\lib\site-packages\django\template\base.py", line 879, in _resolve_lookup
    current = current[bit]
  File "E:\Education\GitHub Projects\PhDPortal\env\lib\site-packages\django\template\context.py", line 77, in __getitem__
    raise KeyError(key)
KeyError: 'TIME_ZONE'

During handling of the above exception, another exception occurred:

Traceback (most recent call last):
  File "E:\Education\GitHub Projects\PhDPortal\env\lib\site-packages\django\template\base.py", line 885, in _resolve_lookup
    if isinstance(current, BaseContext) and getattr(type(current), bit):
AttributeError: type object 'RequestContext' has no attribute 'TIME_ZONE'

During handling of the above exception, another exception occurred:

Traceback (most recent call last):
  File "E:\Education\GitHub Projects\PhDPortal\env\lib\site-packages\django\template\base.py", line 894, in _resolve_lookup
    current = current[int(bit)]
ValueError: invalid literal for int() with base 10: 'TIME_ZONE'

During handling of the above exception, another exception occurred:

Traceback (most recent call last):
  File "E:\Education\GitHub Projects\PhDPortal\env\lib\site-packages\django\core\handlers\base.py", line 149, in get_response
    response = self.process_exception_by_middleware(e, request)
  File "E:\Education\GitHub Projects\PhDPortal\env\lib\site-packages\django\core\handlers\base.py", line 147, in get_response
    response = wrapped_callback(request, *callback_args, **callback_kwargs)
  File "E:\Education\GitHub Projects\PhDPortal\env\lib\site-packages\django\contrib\auth\decorators.py", line 23, in _wrapped_view
    return view_func(request, *args, **kwargs)
  File "E:\Education\GitHub Projects\PhDPortal\app\views.py", line 434, in user_notifications
    'unread_notifications': unread_notifications,
  File "E:\Education\GitHub Projects\PhDPortal\env\lib\site-packages\django\shortcuts.py", line 67, in render
    template_name, context, request=request, using=using)
  File "E:\Education\GitHub Projects\PhDPortal\env\lib\site-packages\django\template\loader.py", line 97, in render_to_string
    return template.render(context, request)
  File "E:\Education\GitHub Projects\PhDPortal\env\lib\site-packages\django\template\backends\django.py", line 95, in render
    return self.template.render(context)
  File "E:\Education\GitHub Projects\PhDPortal\env\lib\site-packages\django\template\base.py", line 206, in render
    return self._render(context)
  File "E:\Education\GitHub Projects\PhDPortal\env\lib\site-packages\django\template\base.py", line 197, in _render
    return self.nodelist.render(context)
  File "E:\Education\GitHub Projects\PhDPortal\env\lib\site-packages\django\template\base.py", line 988, in render
    bit = node.render_annotated(context)
  File "E:\Education\GitHub Projects\PhDPortal\env\lib\site-packages\django\template\base.py", line 955, in render_annotated
    return self.render(context)
  File "E:\Education\GitHub Projects\PhDPortal\env\lib\site-packages\django\template\loader_tags.py", line 173, in render
    return compiled_parent._render(context)
  File "E:\Education\GitHub Projects\PhDPortal\env\lib\site-packages\django\template\base.py", line 197, in _render
    return self.nodelist.render(context)
  File "E:\Education\GitHub Projects\PhDPortal\env\lib\site-packages\django\template\base.py", line 988, in render
    bit = node.render_annotated(context)
  File "E:\Education\GitHub Projects\PhDPortal\env\lib\site-packages\django\template\base.py", line 955, in render_annotated
    return self.render(context)
  File "E:\Education\GitHub Projects\PhDPortal\env\lib\site-packages\django\template\loader_tags.py", line 69, in render
    result = block.nodelist.render(context)
  File "E:\Education\GitHub Projects\PhDPortal\env\lib\site-packages\django\template\base.py", line 988, in render
    bit = node.render_annotated(context)
  File "E:\Education\GitHub Projects\PhDPortal\env\lib\site-packages\django\template\base.py", line 955, in render_annotated
    return self.render(context)
  File "E:\Education\GitHub Projects\PhDPortal\env\lib\site-packages\django\template\defaulttags.py", line 326, in render
    return nodelist.render(context)
  File "E:\Education\GitHub Projects\PhDPortal\env\lib\site-packages\django\template\base.py", line 988, in render
    bit = node.render_annotated(context)
  File "E:\Education\GitHub Projects\PhDPortal\env\lib\site-packages\django\template\base.py", line 955, in render_annotated
    return self.render(context)
  File "E:\Education\GitHub Projects\PhDPortal\env\lib\site-packages\django\template\defaulttags.py", line 220, in render
    nodelist.append(node.render_annotated(context))
  File "E:\Education\GitHub Projects\PhDPortal\env\lib\site-packages\django\template\base.py", line 955, in render_annotated
    return self.render(context)
  File "E:\Education\GitHub Projects\PhDPortal\env\lib\site-packages\django\template\base.py", line 1039, in render
    output = self.filter_expression.resolve(context)
  File "E:\Education\GitHub Projects\PhDPortal\env\lib\site-packages\django\template\base.py", line 726, in resolve
    arg_vals.append(arg.resolve(context))
  File "E:\Education\GitHub Projects\PhDPortal\env\lib\site-packages\django\template\base.py", line 846, in resolve
    value = self._resolve_lookup(context)
  File "E:\Education\GitHub Projects\PhDPortal\env\lib\site-packages\django\template\base.py", line 901, in _resolve_lookup
    (bit, current))  # missing attribute
django.template.base.VariableDoesNotExist: Failed lookup for key [TIME_ZONE] in "[{'True': True, 'False': False, 'None': None}, {}, {}, {'title': 'Notifications', 'layout_data': {'unread_notifications_count': 6, 'unread_notifications': [<Notification:  notification>, <Notification:  notification>, <Notification:  notification>]}, 'read_notifications': [<Notification:  notification>, <Notification:  notification>, <Notification:  notification>], 'unread_notifications': [<Notification:  notification>, <Notification:  notification>, <Notification:  notification>, <Notification:  notification>, <Notification:  notification>, <Notification:  notification>]}]"
2017-04-03 18:14:36 - ERROR - base:handle_uncaught_exception:284 - Internal Server Error: /user/notifications/
Traceback (most recent call last):
  File "E:\Education\GitHub Projects\PhDPortal\env\lib\site-packages\django\core\handlers\base.py", line 149, in get_response
    response = self.process_exception_by_middleware(e, request)
  File "E:\Education\GitHub Projects\PhDPortal\env\lib\site-packages\django\core\handlers\base.py", line 147, in get_response
    response = wrapped_callback(request, *callback_args, **callback_kwargs)
  File "E:\Education\GitHub Projects\PhDPortal\env\lib\site-packages\django\contrib\auth\decorators.py", line 23, in _wrapped_view
    return view_func(request, *args, **kwargs)
  File "E:\Education\GitHub Projects\PhDPortal\app\views.py", line 434, in user_notifications
    'unread_notifications': unread_notifications,
  File "E:\Education\GitHub Projects\PhDPortal\env\lib\site-packages\django\shortcuts.py", line 67, in render
    template_name, context, request=request, using=using)
  File "E:\Education\GitHub Projects\PhDPortal\env\lib\site-packages\django\template\loader.py", line 97, in render_to_string
    return template.render(context, request)
  File "E:\Education\GitHub Projects\PhDPortal\env\lib\site-packages\django\template\backends\django.py", line 95, in render
    return self.template.render(context)
  File "E:\Education\GitHub Projects\PhDPortal\env\lib\site-packages\django\template\base.py", line 206, in render
    return self._render(context)
  File "E:\Education\GitHub Projects\PhDPortal\env\lib\site-packages\django\template\base.py", line 197, in _render
    return self.nodelist.render(context)
  File "E:\Education\GitHub Projects\PhDPortal\env\lib\site-packages\django\template\base.py", line 988, in render
    bit = node.render_annotated(context)
  File "E:\Education\GitHub Projects\PhDPortal\env\lib\site-packages\django\template\base.py", line 955, in render_annotated
    return self.render(context)
  File "E:\Education\GitHub Projects\PhDPortal\env\lib\site-packages\django\template\loader_tags.py", line 173, in render
    return compiled_parent._render(context)
  File "E:\Education\GitHub Projects\PhDPortal\env\lib\site-packages\django\template\base.py", line 197, in _render
    return self.nodelist.render(context)
  File "E:\Education\GitHub Projects\PhDPortal\env\lib\site-packages\django\template\base.py", line 988, in render
    bit = node.render_annotated(context)
  File "E:\Education\GitHub Projects\PhDPortal\env\lib\site-packages\django\template\base.py", line 955, in render_annotated
    return self.render(context)
  File "E:\Education\GitHub Projects\PhDPortal\env\lib\site-packages\django\template\loader_tags.py", line 69, in render
    result = block.nodelist.render(context)
  File "E:\Education\GitHub Projects\PhDPortal\env\lib\site-packages\django\template\base.py", line 988, in render
    bit = node.render_annotated(context)
  File "E:\Education\GitHub Projects\PhDPortal\env\lib\site-packages\django\template\base.py", line 955, in render_annotated
    return self.render(context)
  File "E:\Education\GitHub Projects\PhDPortal\env\lib\site-packages\django\template\defaulttags.py", line 326, in render
    return nodelist.render(context)
  File "E:\Education\GitHub Projects\PhDPortal\env\lib\site-packages\django\template\base.py", line 988, in render
    bit = node.render_annotated(context)
  File "E:\Education\GitHub Projects\PhDPortal\env\lib\site-packages\django\template\base.py", line 955, in render_annotated
    return self.render(context)
  File "E:\Education\GitHub Projects\PhDPortal\env\lib\site-packages\django\template\defaulttags.py", line 220, in render
    nodelist.append(node.render_annotated(context))
  File "E:\Education\GitHub Projects\PhDPortal\env\lib\site-packages\django\template\base.py", line 955, in render_annotated
    return self.render(context)
  File "E:\Education\GitHub Projects\PhDPortal\env\lib\site-packages\django\templatetags\tz.py", line 113, in render
    with timezone.override(self.tz.resolve(context)):
  File "E:\Education\GitHub Projects\PhDPortal\env\lib\site-packages\django\utils\timezone.py", line 269, in __enter__
    activate(self.timezone)
  File "E:\Education\GitHub Projects\PhDPortal\env\lib\site-packages\django\utils\timezone.py", line 234, in activate
    _active.value = pytz.timezone(timezone)
  File "E:\Education\GitHub Projects\PhDPortal\env\lib\site-packages\pytz\__init__.py", line 181, in timezone
    raise UnknownTimeZoneError(zone)
pytz.exceptions.UnknownTimeZoneError: ''
2017-04-03 18:22:44 - ERROR - base:handle_uncaught_exception:284 - Internal Server Error: /user/notifications/
Traceback (most recent call last):
  File "E:\Education\GitHub Projects\PhDPortal\env\lib\site-packages\django\core\handlers\base.py", line 149, in get_response
    response = self.process_exception_by_middleware(e, request)
  File "E:\Education\GitHub Projects\PhDPortal\env\lib\site-packages\django\core\handlers\base.py", line 147, in get_response
    response = wrapped_callback(request, *callback_args, **callback_kwargs)
  File "E:\Education\GitHub Projects\PhDPortal\env\lib\site-packages\django\contrib\auth\decorators.py", line 23, in _wrapped_view
    return view_func(request, *args, **kwargs)
  File "E:\Education\GitHub Projects\PhDPortal\app\views.py", line 434, in user_notifications
    'unread_notifications': unread_notifications,
  File "E:\Education\GitHub Projects\PhDPortal\env\lib\site-packages\django\shortcuts.py", line 67, in render
    template_name, context, request=request, using=using)
  File "E:\Education\GitHub Projects\PhDPortal\env\lib\site-packages\django\template\loader.py", line 97, in render_to_string
    return template.render(context, request)
  File "E:\Education\GitHub Projects\PhDPortal\env\lib\site-packages\django\template\backends\django.py", line 95, in render
    return self.template.render(context)
  File "E:\Education\GitHub Projects\PhDPortal\env\lib\site-packages\django\template\base.py", line 206, in render
    return self._render(context)
  File "E:\Education\GitHub Projects\PhDPortal\env\lib\site-packages\django\template\base.py", line 197, in _render
    return self.nodelist.render(context)
  File "E:\Education\GitHub Projects\PhDPortal\env\lib\site-packages\django\template\base.py", line 988, in render
    bit = node.render_annotated(context)
  File "E:\Education\GitHub Projects\PhDPortal\env\lib\site-packages\django\template\base.py", line 955, in render_annotated
    return self.render(context)
  File "E:\Education\GitHub Projects\PhDPortal\env\lib\site-packages\django\template\loader_tags.py", line 173, in render
    return compiled_parent._render(context)
  File "E:\Education\GitHub Projects\PhDPortal\env\lib\site-packages\django\template\base.py", line 197, in _render
    return self.nodelist.render(context)
  File "E:\Education\GitHub Projects\PhDPortal\env\lib\site-packages\django\template\base.py", line 988, in render
    bit = node.render_annotated(context)
  File "E:\Education\GitHub Projects\PhDPortal\env\lib\site-packages\django\template\base.py", line 955, in render_annotated
    return self.render(context)
  File "E:\Education\GitHub Projects\PhDPortal\env\lib\site-packages\django\template\loader_tags.py", line 69, in render
    result = block.nodelist.render(context)
  File "E:\Education\GitHub Projects\PhDPortal\env\lib\site-packages\django\template\base.py", line 988, in render
    bit = node.render_annotated(context)
  File "E:\Education\GitHub Projects\PhDPortal\env\lib\site-packages\django\template\base.py", line 955, in render_annotated
    return self.render(context)
  File "E:\Education\GitHub Projects\PhDPortal\env\lib\site-packages\django\template\defaulttags.py", line 326, in render
    return nodelist.render(context)
  File "E:\Education\GitHub Projects\PhDPortal\env\lib\site-packages\django\template\base.py", line 988, in render
    bit = node.render_annotated(context)
  File "E:\Education\GitHub Projects\PhDPortal\env\lib\site-packages\django\template\base.py", line 955, in render_annotated
    return self.render(context)
  File "E:\Education\GitHub Projects\PhDPortal\env\lib\site-packages\django\template\defaulttags.py", line 220, in render
    nodelist.append(node.render_annotated(context))
  File "E:\Education\GitHub Projects\PhDPortal\env\lib\site-packages\django\template\base.py", line 955, in render_annotated
    return self.render(context)
  File "E:\Education\GitHub Projects\PhDPortal\env\lib\site-packages\django\templatetags\tz.py", line 113, in render
    with timezone.override(self.tz.resolve(context)):
  File "E:\Education\GitHub Projects\PhDPortal\env\lib\site-packages\django\utils\timezone.py", line 269, in __enter__
    activate(self.timezone)
  File "E:\Education\GitHub Projects\PhDPortal\env\lib\site-packages\django\utils\timezone.py", line 234, in activate
    _active.value = pytz.timezone(timezone)
  File "E:\Education\GitHub Projects\PhDPortal\env\lib\site-packages\pytz\__init__.py", line 181, in timezone
    raise UnknownTimeZoneError(zone)
pytz.exceptions.UnknownTimeZoneError: ''
2017-04-03 18:23:03 - ERROR - base:handle_uncaught_exception:284 - Internal Server Error: /user/notifications/
Traceback (most recent call last):
  File "E:\Education\GitHub Projects\PhDPortal\env\lib\site-packages\django\core\handlers\base.py", line 149, in get_response
    response = self.process_exception_by_middleware(e, request)
  File "E:\Education\GitHub Projects\PhDPortal\env\lib\site-packages\django\core\handlers\base.py", line 147, in get_response
    response = wrapped_callback(request, *callback_args, **callback_kwargs)
  File "E:\Education\GitHub Projects\PhDPortal\env\lib\site-packages\django\contrib\auth\decorators.py", line 23, in _wrapped_view
    return view_func(request, *args, **kwargs)
  File "E:\Education\GitHub Projects\PhDPortal\app\views.py", line 434, in user_notifications
    'unread_notifications': unread_notifications,
  File "E:\Education\GitHub Projects\PhDPortal\env\lib\site-packages\django\shortcuts.py", line 67, in render
    template_name, context, request=request, using=using)
  File "E:\Education\GitHub Projects\PhDPortal\env\lib\site-packages\django\template\loader.py", line 97, in render_to_string
    return template.render(context, request)
  File "E:\Education\GitHub Projects\PhDPortal\env\lib\site-packages\django\template\backends\django.py", line 95, in render
    return self.template.render(context)
  File "E:\Education\GitHub Projects\PhDPortal\env\lib\site-packages\django\template\base.py", line 206, in render
    return self._render(context)
  File "E:\Education\GitHub Projects\PhDPortal\env\lib\site-packages\django\template\base.py", line 197, in _render
    return self.nodelist.render(context)
  File "E:\Education\GitHub Projects\PhDPortal\env\lib\site-packages\django\template\base.py", line 988, in render
    bit = node.render_annotated(context)
  File "E:\Education\GitHub Projects\PhDPortal\env\lib\site-packages\django\template\base.py", line 955, in render_annotated
    return self.render(context)
  File "E:\Education\GitHub Projects\PhDPortal\env\lib\site-packages\django\template\loader_tags.py", line 173, in render
    return compiled_parent._render(context)
  File "E:\Education\GitHub Projects\PhDPortal\env\lib\site-packages\django\template\base.py", line 197, in _render
    return self.nodelist.render(context)
  File "E:\Education\GitHub Projects\PhDPortal\env\lib\site-packages\django\template\base.py", line 988, in render
    bit = node.render_annotated(context)
  File "E:\Education\GitHub Projects\PhDPortal\env\lib\site-packages\django\template\base.py", line 955, in render_annotated
    return self.render(context)
  File "E:\Education\GitHub Projects\PhDPortal\env\lib\site-packages\django\template\loader_tags.py", line 69, in render
    result = block.nodelist.render(context)
  File "E:\Education\GitHub Projects\PhDPortal\env\lib\site-packages\django\template\base.py", line 988, in render
    bit = node.render_annotated(context)
  File "E:\Education\GitHub Projects\PhDPortal\env\lib\site-packages\django\template\base.py", line 955, in render_annotated
    return self.render(context)
  File "E:\Education\GitHub Projects\PhDPortal\env\lib\site-packages\django\template\defaulttags.py", line 326, in render
    return nodelist.render(context)
  File "E:\Education\GitHub Projects\PhDPortal\env\lib\site-packages\django\template\base.py", line 988, in render
    bit = node.render_annotated(context)
  File "E:\Education\GitHub Projects\PhDPortal\env\lib\site-packages\django\template\base.py", line 955, in render_annotated
    return self.render(context)
  File "E:\Education\GitHub Projects\PhDPortal\env\lib\site-packages\django\template\defaulttags.py", line 220, in render
    nodelist.append(node.render_annotated(context))
  File "E:\Education\GitHub Projects\PhDPortal\env\lib\site-packages\django\template\base.py", line 955, in render_annotated
    return self.render(context)
  File "E:\Education\GitHub Projects\PhDPortal\env\lib\site-packages\django\templatetags\tz.py", line 113, in render
    with timezone.override(self.tz.resolve(context)):
  File "E:\Education\GitHub Projects\PhDPortal\env\lib\site-packages\django\utils\timezone.py", line 269, in __enter__
    activate(self.timezone)
  File "E:\Education\GitHub Projects\PhDPortal\env\lib\site-packages\django\utils\timezone.py", line 234, in activate
    _active.value = pytz.timezone(timezone)
  File "E:\Education\GitHub Projects\PhDPortal\env\lib\site-packages\pytz\__init__.py", line 181, in timezone
    raise UnknownTimeZoneError(zone)
pytz.exceptions.UnknownTimeZoneError: ''
2017-04-03 18:26:03 - ERROR - base:handle_uncaught_exception:284 - Internal Server Error: /user/notifications/
Traceback (most recent call last):
  File "E:\Education\GitHub Projects\PhDPortal\env\lib\site-packages\django\core\handlers\base.py", line 149, in get_response
    response = self.process_exception_by_middleware(e, request)
  File "E:\Education\GitHub Projects\PhDPortal\env\lib\site-packages\django\core\handlers\base.py", line 147, in get_response
    response = wrapped_callback(request, *callback_args, **callback_kwargs)
  File "E:\Education\GitHub Projects\PhDPortal\env\lib\site-packages\django\contrib\auth\decorators.py", line 23, in _wrapped_view
    return view_func(request, *args, **kwargs)
  File "E:\Education\GitHub Projects\PhDPortal\app\views.py", line 436, in user_notifications
    'TZ' : timezone.get_current_timezone(),
NameError: name 'timezone' is not defined
2017-04-03 18:26:33 - ERROR - base:handle_uncaught_exception:284 - Internal Server Error: /user/notifications/
Traceback (most recent call last):
  File "E:\Education\GitHub Projects\PhDPortal\env\lib\site-packages\django\core\handlers\base.py", line 149, in get_response
    response = self.process_exception_by_middleware(e, request)
  File "E:\Education\GitHub Projects\PhDPortal\env\lib\site-packages\django\core\handlers\base.py", line 147, in get_response
    response = wrapped_callback(request, *callback_args, **callback_kwargs)
  File "E:\Education\GitHub Projects\PhDPortal\env\lib\site-packages\django\contrib\auth\decorators.py", line 23, in _wrapped_view
    return view_func(request, *args, **kwargs)
  File "E:\Education\GitHub Projects\PhDPortal\app\views.py", line 436, in user_notifications
    'TZ' : timezone.get_current_timezone(),
NameError: name 'timezone' is not defined
2017-04-03 18:33:10 - ERROR - base:handle_uncaught_exception:284 - Internal Server Error: /user/notifications/
Traceback (most recent call last):
  File "E:\Education\GitHub Projects\PhDPortal\env\lib\site-packages\django\core\handlers\base.py", line 149, in get_response
    response = self.process_exception_by_middleware(e, request)
  File "E:\Education\GitHub Projects\PhDPortal\env\lib\site-packages\django\core\handlers\base.py", line 147, in get_response
    response = wrapped_callback(request, *callback_args, **callback_kwargs)
  File "E:\Education\GitHub Projects\PhDPortal\env\lib\site-packages\django\contrib\auth\decorators.py", line 23, in _wrapped_view
    return view_func(request, *args, **kwargs)
  File "E:\Education\GitHub Projects\PhDPortal\app\views.py", line 428, in user_notifications
    activate(settings.TIME_ZONE)
NameError: name 'settings' is not defined
2017-04-03 19:15:06 - ERROR - base:handle_uncaught_exception:284 - Internal Server Error: /user/notifications/
Traceback (most recent call last):
  File "E:\Education\GitHub Projects\PhDPortal\env\lib\site-packages\django\core\handlers\base.py", line 149, in get_response
    response = self.process_exception_by_middleware(e, request)
  File "E:\Education\GitHub Projects\PhDPortal\env\lib\site-packages\django\core\handlers\base.py", line 147, in get_response
    response = wrapped_callback(request, *callback_args, **callback_kwargs)
  File "E:\Education\GitHub Projects\PhDPortal\env\lib\site-packages\django\contrib\auth\decorators.py", line 23, in _wrapped_view
    return view_func(request, *args, **kwargs)
  File "E:\Education\GitHub Projects\PhDPortal\app\views.py", line 428, in user_notifications
    date = datetime.now(get_localzone())
NameError: name 'datetime' is not defined
2017-04-03 20:31:20 - INFO - views:login:352 - User ash successfully authenticated
2017-04-03 20:32:48 - INFO - views:login:352 - User angelina successfully authenticated
2017-04-03 20:33:38 - INFO - views:login:352 - User anshul successfully authenticated
2017-04-03 20:34:00 - INFO - views:login:352 - User ash successfully authenticated
2017-04-17 15:28:48 - INFO - views:login:390 - User anshul successfully authenticated
2017-04-18 11:59:24 - INFO - views:login:390 - User anshul successfully authenticated
2017-04-18 12:00:22 - INFO - views:logout:412 - User anshul successfully logged out
2017-04-18 12:00:30 - INFO - views:login:390 - User pavan successfully authenticated
2017-04-18 12:01:36 - INFO - views:logout:412 - User pavan successfully logged out
2017-04-18 12:03:06 - INFO - views:login:390 - User admin successfully authenticated
2017-04-18 12:04:23 - INFO - views:logout:412 - User admin successfully logged out
2017-04-18 12:04:30 - INFO - views:login:390 - User gcnandi successfully authenticated
2017-04-18 12:05:02 - INFO - views:logout:412 - User gcnandi successfully logged out
2017-04-18 12:05:16 - INFO - views:login:390 - User angelina successfully authenticated
2017-04-18 12:06:51 - ERROR - base:handle_uncaught_exception:284 - Internal Server Error: /admin/app/thesis/
Traceback (most recent call last):
  File "E:\Education\GitHub Projects\PhDPortal\env\lib\site-packages\django\core\handlers\base.py", line 149, in get_response
    response = self.process_exception_by_middleware(e, request)
  File "E:\Education\GitHub Projects\PhDPortal\env\lib\site-packages\django\core\handlers\base.py", line 147, in get_response
    response = wrapped_callback(request, *callback_args, **callback_kwargs)
  File "E:\Education\GitHub Projects\PhDPortal\env\lib\site-packages\django\contrib\admin\options.py", line 541, in wrapper
    return self.admin_site.admin_view(view)(*args, **kwargs)
  File "E:\Education\GitHub Projects\PhDPortal\env\lib\site-packages\django\utils\decorators.py", line 149, in _wrapped_view
    response = view_func(request, *args, **kwargs)
  File "E:\Education\GitHub Projects\PhDPortal\env\lib\site-packages\django\views\decorators\cache.py", line 57, in _wrapped_view_func
    response = view_func(request, *args, **kwargs)
  File "E:\Education\GitHub Projects\PhDPortal\env\lib\site-packages\django\contrib\admin\sites.py", line 244, in inner
    return view(request, *args, **kwargs)
  File "E:\Education\GitHub Projects\PhDPortal\env\lib\site-packages\django\utils\decorators.py", line 67, in _wrapper
    return bound_func(*args, **kwargs)
  File "E:\Education\GitHub Projects\PhDPortal\env\lib\site-packages\django\utils\decorators.py", line 149, in _wrapped_view
    response = view_func(request, *args, **kwargs)
  File "E:\Education\GitHub Projects\PhDPortal\env\lib\site-packages\django\utils\decorators.py", line 63, in bound_func
    return func.__get__(self, type(self))(*args2, **kwargs2)
  File "E:\Education\GitHub Projects\PhDPortal\env\lib\site-packages\django\contrib\admin\options.py", line 1468, in changelist_view
    self.list_max_show_all, self.list_editable, self)
  File "E:\Education\GitHub Projects\PhDPortal\env\lib\site-packages\django\contrib\admin\views\main.py", line 78, in __init__
    self.queryset = self.get_queryset(request)
  File "E:\Education\GitHub Projects\PhDPortal\env\lib\site-packages\django\contrib\admin\views\main.py", line 356, in get_queryset
    request, qs, self.query)
  File "E:\Education\GitHub Projects\PhDPortal\env\lib\site-packages\django\contrib\admin\options.py", line 900, in get_search_results
    queryset = queryset.filter(reduce(operator.or_, or_queries))
  File "E:\Education\GitHub Projects\PhDPortal\env\lib\site-packages\django\db\models\query.py", line 790, in filter
    return self._filter_or_exclude(False, *args, **kwargs)
  File "E:\Education\GitHub Projects\PhDPortal\env\lib\site-packages\django\db\models\query.py", line 808, in _filter_or_exclude
    clone.query.add_q(Q(*args, **kwargs))
  File "E:\Education\GitHub Projects\PhDPortal\env\lib\site-packages\django\db\models\sql\query.py", line 1243, in add_q
    clause, _ = self._add_q(q_object, self.used_aliases)
  File "E:\Education\GitHub Projects\PhDPortal\env\lib\site-packages\django\db\models\sql\query.py", line 1263, in _add_q
    current_negated, allow_joins, split_subq)
  File "E:\Education\GitHub Projects\PhDPortal\env\lib\site-packages\django\db\models\sql\query.py", line 1269, in _add_q
    allow_joins=allow_joins, split_subq=split_subq,
  File "E:\Education\GitHub Projects\PhDPortal\env\lib\site-packages\django\db\models\sql\query.py", line 1194, in build_filter
    lookup_class = field.get_lookup(lookups[0])
  File "E:\Education\GitHub Projects\PhDPortal\env\lib\site-packages\django\db\models\fields\related.py", line 688, in get_lookup
    raise TypeError('Related Field got invalid lookup: %s' % lookup_name)
TypeError: Related Field got invalid lookup: icontains
2017-04-18 12:07:14 - ERROR - base:handle_uncaught_exception:284 - Internal Server Error: /admin/app/thesis/
Traceback (most recent call last):
  File "E:\Education\GitHub Projects\PhDPortal\env\lib\site-packages\django\core\handlers\base.py", line 149, in get_response
    response = self.process_exception_by_middleware(e, request)
  File "E:\Education\GitHub Projects\PhDPortal\env\lib\site-packages\django\core\handlers\base.py", line 147, in get_response
    response = wrapped_callback(request, *callback_args, **callback_kwargs)
  File "E:\Education\GitHub Projects\PhDPortal\env\lib\site-packages\django\contrib\admin\options.py", line 541, in wrapper
    return self.admin_site.admin_view(view)(*args, **kwargs)
  File "E:\Education\GitHub Projects\PhDPortal\env\lib\site-packages\django\utils\decorators.py", line 149, in _wrapped_view
    response = view_func(request, *args, **kwargs)
  File "E:\Education\GitHub Projects\PhDPortal\env\lib\site-packages\django\views\decorators\cache.py", line 57, in _wrapped_view_func
    response = view_func(request, *args, **kwargs)
  File "E:\Education\GitHub Projects\PhDPortal\env\lib\site-packages\django\contrib\admin\sites.py", line 244, in inner
    return view(request, *args, **kwargs)
  File "E:\Education\GitHub Projects\PhDPortal\env\lib\site-packages\django\utils\decorators.py", line 67, in _wrapper
    return bound_func(*args, **kwargs)
  File "E:\Education\GitHub Projects\PhDPortal\env\lib\site-packages\django\utils\decorators.py", line 149, in _wrapped_view
    response = view_func(request, *args, **kwargs)
  File "E:\Education\GitHub Projects\PhDPortal\env\lib\site-packages\django\utils\decorators.py", line 63, in bound_func
    return func.__get__(self, type(self))(*args2, **kwargs2)
  File "E:\Education\GitHub Projects\PhDPortal\env\lib\site-packages\django\contrib\admin\options.py", line 1468, in changelist_view
    self.list_max_show_all, self.list_editable, self)
  File "E:\Education\GitHub Projects\PhDPortal\env\lib\site-packages\django\contrib\admin\views\main.py", line 78, in __init__
    self.queryset = self.get_queryset(request)
  File "E:\Education\GitHub Projects\PhDPortal\env\lib\site-packages\django\contrib\admin\views\main.py", line 356, in get_queryset
    request, qs, self.query)
  File "E:\Education\GitHub Projects\PhDPortal\env\lib\site-packages\django\contrib\admin\options.py", line 900, in get_search_results
    queryset = queryset.filter(reduce(operator.or_, or_queries))
  File "E:\Education\GitHub Projects\PhDPortal\env\lib\site-packages\django\db\models\query.py", line 790, in filter
    return self._filter_or_exclude(False, *args, **kwargs)
  File "E:\Education\GitHub Projects\PhDPortal\env\lib\site-packages\django\db\models\query.py", line 808, in _filter_or_exclude
    clone.query.add_q(Q(*args, **kwargs))
  File "E:\Education\GitHub Projects\PhDPortal\env\lib\site-packages\django\db\models\sql\query.py", line 1243, in add_q
    clause, _ = self._add_q(q_object, self.used_aliases)
  File "E:\Education\GitHub Projects\PhDPortal\env\lib\site-packages\django\db\models\sql\query.py", line 1263, in _add_q
    current_negated, allow_joins, split_subq)
  File "E:\Education\GitHub Projects\PhDPortal\env\lib\site-packages\django\db\models\sql\query.py", line 1269, in _add_q
    allow_joins=allow_joins, split_subq=split_subq,
  File "E:\Education\GitHub Projects\PhDPortal\env\lib\site-packages\django\db\models\sql\query.py", line 1194, in build_filter
    lookup_class = field.get_lookup(lookups[0])
  File "E:\Education\GitHub Projects\PhDPortal\env\lib\site-packages\django\db\models\fields\related.py", line 688, in get_lookup
    raise TypeError('Related Field got invalid lookup: %s' % lookup_name)
TypeError: Related Field got invalid lookup: icontains
2017-04-18 12:10:43 - INFO - views:logout:412 - User angelina successfully logged out
2017-04-18 12:10:48 - INFO - views:login:390 - User anshul successfully authenticated
2017-04-18 12:14:15 - INFO - views:logout:412 - User anshul successfully logged out
2017-04-18 12:14:26 - INFO - views:login:390 - User kishore successfully authenticated
2017-04-18 12:15:14 - INFO - views:logout:412 - User kishore successfully logged out
2017-04-18 12:15:22 - INFO - views:login:390 - User janit successfully authenticated
2017-04-18 12:15:54 - INFO - views:logout:412 - User janit successfully logged out
2017-04-18 12:42:31 - INFO - views:login:390 - User anshul successfully authenticated
2017-04-18 12:54:39 - INFO - views:login:390 - User anshul successfully authenticated
2017-04-18 17:59:39 - INFO - views:login:390 - User anshul successfully authenticated
2017-04-18 18:28:08 - ERROR - base:handle_uncaught_exception:284 - Internal Server Error: /student/keywords/
Traceback (most recent call last):
  File "E:\Education\GitHub Projects\PhDPortal\env\lib\site-packages\django\template\defaulttags.py", line 507, in render
    current_app=current_app)
  File "E:\Education\GitHub Projects\PhDPortal\env\lib\site-packages\django\core\urlresolvers.py", line 600, in reverse
    return force_text(iri_to_uri(resolver._reverse_with_prefix(view, prefix, *args, **kwargs)))
  File "E:\Education\GitHub Projects\PhDPortal\env\lib\site-packages\django\core\urlresolvers.py", line 508, in _reverse_with_prefix
    (lookup_view_s, args, kwargs, len(patterns), patterns))
django.core.urlresolvers.NoReverseMatch: Reverse for 'PhDPortal.search-keywords' with arguments '()' and keyword arguments '{}' not found. 0 pattern(s) tried: []

During handling of the above exception, another exception occurred:

Traceback (most recent call last):
  File "E:\Education\GitHub Projects\PhDPortal\env\lib\site-packages\django\core\handlers\base.py", line 149, in get_response
    response = self.process_exception_by_middleware(e, request)
  File "E:\Education\GitHub Projects\PhDPortal\env\lib\site-packages\django\core\handlers\base.py", line 147, in get_response
    response = wrapped_callback(request, *callback_args, **callback_kwargs)
  File "E:\Education\GitHub Projects\PhDPortal\env\lib\site-packages\django\contrib\auth\decorators.py", line 23, in _wrapped_view
    return view_func(request, *args, **kwargs)
  File "E:\Education\GitHub Projects\PhDPortal\app\student_views.py", line 421, in student_add_keywords
    'thesis_keywords' : thesis_keywords,
  File "E:\Education\GitHub Projects\PhDPortal\env\lib\site-packages\django\shortcuts.py", line 67, in render
    template_name, context, request=request, using=using)
  File "E:\Education\GitHub Projects\PhDPortal\env\lib\site-packages\django\template\loader.py", line 97, in render_to_string
    return template.render(context, request)
  File "E:\Education\GitHub Projects\PhDPortal\env\lib\site-packages\django\template\backends\django.py", line 95, in render
    return self.template.render(context)
  File "E:\Education\GitHub Projects\PhDPortal\env\lib\site-packages\django\template\base.py", line 206, in render
    return self._render(context)
  File "E:\Education\GitHub Projects\PhDPortal\env\lib\site-packages\django\template\base.py", line 197, in _render
    return self.nodelist.render(context)
  File "E:\Education\GitHub Projects\PhDPortal\env\lib\site-packages\django\template\base.py", line 988, in render
    bit = node.render_annotated(context)
  File "E:\Education\GitHub Projects\PhDPortal\env\lib\site-packages\django\template\base.py", line 955, in render_annotated
    return self.render(context)
  File "E:\Education\GitHub Projects\PhDPortal\env\lib\site-packages\django\template\loader_tags.py", line 173, in render
    return compiled_parent._render(context)
  File "E:\Education\GitHub Projects\PhDPortal\env\lib\site-packages\django\template\base.py", line 197, in _render
    return self.nodelist.render(context)
  File "E:\Education\GitHub Projects\PhDPortal\env\lib\site-packages\django\template\base.py", line 988, in render
    bit = node.render_annotated(context)
  File "E:\Education\GitHub Projects\PhDPortal\env\lib\site-packages\django\template\base.py", line 955, in render_annotated
    return self.render(context)
  File "E:\Education\GitHub Projects\PhDPortal\env\lib\site-packages\django\template\loader_tags.py", line 69, in render
    result = block.nodelist.render(context)
  File "E:\Education\GitHub Projects\PhDPortal\env\lib\site-packages\django\template\base.py", line 988, in render
    bit = node.render_annotated(context)
  File "E:\Education\GitHub Projects\PhDPortal\env\lib\site-packages\django\template\base.py", line 955, in render_annotated
    return self.render(context)
  File "E:\Education\GitHub Projects\PhDPortal\env\lib\site-packages\django\template\defaulttags.py", line 326, in render
    return nodelist.render(context)
  File "E:\Education\GitHub Projects\PhDPortal\env\lib\site-packages\django\template\base.py", line 988, in render
    bit = node.render_annotated(context)
  File "E:\Education\GitHub Projects\PhDPortal\env\lib\site-packages\django\template\base.py", line 955, in render_annotated
    return self.render(context)
  File "E:\Education\GitHub Projects\PhDPortal\env\lib\site-packages\django\template\defaulttags.py", line 513, in render
    six.reraise(*exc_info)
  File "E:\Education\GitHub Projects\PhDPortal\env\lib\site-packages\django\utils\six.py", line 686, in reraise
    raise value
  File "E:\Education\GitHub Projects\PhDPortal\env\lib\site-packages\django\template\defaulttags.py", line 499, in render
    url = reverse(view_name, args=args, kwargs=kwargs, current_app=current_app)
  File "E:\Education\GitHub Projects\PhDPortal\env\lib\site-packages\django\core\urlresolvers.py", line 600, in reverse
    return force_text(iri_to_uri(resolver._reverse_with_prefix(view, prefix, *args, **kwargs)))
  File "E:\Education\GitHub Projects\PhDPortal\env\lib\site-packages\django\core\urlresolvers.py", line 508, in _reverse_with_prefix
    (lookup_view_s, args, kwargs, len(patterns), patterns))
django.core.urlresolvers.NoReverseMatch: Reverse for 'search-keywords' with arguments '()' and keyword arguments '{}' not found. 0 pattern(s) tried: []
2017-04-18 18:33:06 - ERROR - base:handle_uncaught_exception:284 - Internal Server Error: /student/keywords/search/
Traceback (most recent call last):
  File "E:\Education\GitHub Projects\PhDPortal\env\lib\site-packages\django\core\handlers\base.py", line 149, in get_response
    response = self.process_exception_by_middleware(e, request)
  File "E:\Education\GitHub Projects\PhDPortal\env\lib\site-packages\django\core\handlers\base.py", line 147, in get_response
    response = wrapped_callback(request, *callback_args, **callback_kwargs)
  File "E:\Education\GitHub Projects\PhDPortal\env\lib\site-packages\django\contrib\auth\decorators.py", line 23, in _wrapped_view
    return view_func(request, *args, **kwargs)
  File "E:\Education\GitHub Projects\PhDPortal\app\student_views.py", line 438, in student_search_keywords
    keywords = IEEEKeyword.objects.icontains(keyword_typed)
AttributeError: 'Manager' object has no attribute 'icontains'
2017-04-18 18:35:51 - ERROR - base:handle_uncaught_exception:284 - Internal Server Error: /student/keywords/search/
Traceback (most recent call last):
  File "E:\Education\GitHub Projects\PhDPortal\env\lib\site-packages\django\core\handlers\base.py", line 149, in get_response
    response = self.process_exception_by_middleware(e, request)
  File "E:\Education\GitHub Projects\PhDPortal\env\lib\site-packages\django\core\handlers\base.py", line 147, in get_response
    response = wrapped_callback(request, *callback_args, **callback_kwargs)
  File "E:\Education\GitHub Projects\PhDPortal\env\lib\site-packages\django\contrib\auth\decorators.py", line 23, in _wrapped_view
    return view_func(request, *args, **kwargs)
  File "E:\Education\GitHub Projects\PhDPortal\app\student_views.py", line 438, in student_search_keywords
    keywords = IEEEKeyword.objects.filter(keyword_icontains = keyword_typed)
  File "E:\Education\GitHub Projects\PhDPortal\env\lib\site-packages\django\db\models\manager.py", line 122, in manager_method
    return getattr(self.get_queryset(), name)(*args, **kwargs)
  File "E:\Education\GitHub Projects\PhDPortal\env\lib\site-packages\django\db\models\query.py", line 790, in filter
    return self._filter_or_exclude(False, *args, **kwargs)
  File "E:\Education\GitHub Projects\PhDPortal\env\lib\site-packages\django\db\models\query.py", line 808, in _filter_or_exclude
    clone.query.add_q(Q(*args, **kwargs))
  File "E:\Education\GitHub Projects\PhDPortal\env\lib\site-packages\django\db\models\sql\query.py", line 1243, in add_q
    clause, _ = self._add_q(q_object, self.used_aliases)
  File "E:\Education\GitHub Projects\PhDPortal\env\lib\site-packages\django\db\models\sql\query.py", line 1269, in _add_q
    allow_joins=allow_joins, split_subq=split_subq,
  File "E:\Education\GitHub Projects\PhDPortal\env\lib\site-packages\django\db\models\sql\query.py", line 1149, in build_filter
    lookups, parts, reffed_expression = self.solve_lookup_type(arg)
  File "E:\Education\GitHub Projects\PhDPortal\env\lib\site-packages\django\db\models\sql\query.py", line 1035, in solve_lookup_type
    _, field, _, lookup_parts = self.names_to_path(lookup_splitted, self.get_meta())
  File "E:\Education\GitHub Projects\PhDPortal\env\lib\site-packages\django\db\models\sql\query.py", line 1330, in names_to_path
    "Choices are: %s" % (name, ", ".join(available)))
django.core.exceptions.FieldError: Cannot resolve keyword 'keyword_icontains' into field. Choices are: id, ieeekeyword, keyword, parent, parent_id, thesiskeyword
2017-04-18 18:36:19 - ERROR - base:handle_uncaught_exception:284 - Internal Server Error: /student/keywords/search/
Traceback (most recent call last):
  File "E:\Education\GitHub Projects\PhDPortal\env\lib\site-packages\django\core\handlers\base.py", line 149, in get_response
    response = self.process_exception_by_middleware(e, request)
  File "E:\Education\GitHub Projects\PhDPortal\env\lib\site-packages\django\core\handlers\base.py", line 147, in get_response
    response = wrapped_callback(request, *callback_args, **callback_kwargs)
  File "E:\Education\GitHub Projects\PhDPortal\env\lib\site-packages\django\contrib\auth\decorators.py", line 23, in _wrapped_view
    return view_func(request, *args, **kwargs)
  File "E:\Education\GitHub Projects\PhDPortal\app\student_views.py", line 440, in student_search_keywords
    return HttpResponse(json.dumps(keywords), content_type = 'application/json')
  File "C:\Python3.6\lib\json\__init__.py", line 231, in dumps
    return _default_encoder.encode(obj)
  File "C:\Python3.6\lib\json\encoder.py", line 199, in encode
    chunks = self.iterencode(o, _one_shot=True)
  File "C:\Python3.6\lib\json\encoder.py", line 257, in iterencode
    return _iterencode(o, 0)
  File "C:\Python3.6\lib\json\encoder.py", line 180, in default
    o.__class__.__name__)
TypeError: Object of type 'QuerySet' is not JSON serializable
2017-04-18 18:38:54 - ERROR - base:handle_uncaught_exception:284 - Internal Server Error: /student/keywords/search/
Traceback (most recent call last):
  File "E:\Education\GitHub Projects\PhDPortal\env\lib\site-packages\django\core\handlers\base.py", line 149, in get_response
    response = self.process_exception_by_middleware(e, request)
  File "E:\Education\GitHub Projects\PhDPortal\env\lib\site-packages\django\core\handlers\base.py", line 147, in get_response
    response = wrapped_callback(request, *callback_args, **callback_kwargs)
  File "E:\Education\GitHub Projects\PhDPortal\env\lib\site-packages\django\contrib\auth\decorators.py", line 23, in _wrapped_view
    return view_func(request, *args, **kwargs)
  File "E:\Education\GitHub Projects\PhDPortal\app\student_views.py", line 440, in student_search_keywords
    return HttpResponse(json.dumps(keywords), content_type = 'application/json')
  File "C:\Python3.6\lib\json\__init__.py", line 231, in dumps
    return _default_encoder.encode(obj)
  File "C:\Python3.6\lib\json\encoder.py", line 199, in encode
    chunks = self.iterencode(o, _one_shot=True)
  File "C:\Python3.6\lib\json\encoder.py", line 257, in iterencode
    return _iterencode(o, 0)
  File "C:\Python3.6\lib\json\encoder.py", line 180, in default
    o.__class__.__name__)
TypeError: Object of type 'IEEEKeyword' is not JSON serializable
2017-04-18 19:20:26 - ERROR - base:handle_uncaught_exception:284 - Internal Server Error: /student/keywords/recommendations/
Traceback (most recent call last):
  File "E:\Education\GitHub Projects\PhDPortal\env\lib\site-packages\django\core\handlers\base.py", line 149, in get_response
    response = self.process_exception_by_middleware(e, request)
  File "E:\Education\GitHub Projects\PhDPortal\env\lib\site-packages\django\core\handlers\base.py", line 147, in get_response
    response = wrapped_callback(request, *callback_args, **callback_kwargs)
  File "E:\Education\GitHub Projects\PhDPortal\env\lib\site-packages\django\contrib\auth\decorators.py", line 23, in _wrapped_view
    return view_func(request, *args, **kwargs)
  File "E:\Education\GitHub Projects\PhDPortal\app\student_views.py", line 456, in student_keyword_recommendations
    thesis = User.objects.get(username = request.session['username']).student.thesis
AttributeError: 'Student' object has no attribute 'thesis'
2017-04-19 18:45:51 - INFO - views:login:390 - User pavan successfully authenticated
2017-04-19 19:49:27 - INFO - views:login:414 - User pavan successfully authenticated
2017-04-19 19:49:57 - ERROR - base:handle_uncaught_exception:284 - Internal Server Error: /guide/feedback/reports/
Traceback (most recent call last):
  File "E:\Education\GitHub Projects\PhDPortal\env\lib\site-packages\django\db\models\fields\related_descriptors.py", line 160, in __get__
    rel_obj = getattr(instance, self.cache_name)
AttributeError: 'PanelMember' object has no attribute '_referee_cache'

During handling of the above exception, another exception occurred:

Traceback (most recent call last):
  File "E:\Education\GitHub Projects\PhDPortal\env\lib\site-packages\django\db\backends\utils.py", line 64, in execute
    return self.cursor.execute(sql, params)
  File "E:\Education\GitHub Projects\PhDPortal\env\lib\site-packages\django\db\backends\sqlite3\base.py", line 323, in execute
    return Database.Cursor.execute(self, query, params)
sqlite3.OperationalError: no such column: app_referee.added_by_id

The above exception was the direct cause of the following exception:

Traceback (most recent call last):
  File "E:\Education\GitHub Projects\PhDPortal\env\lib\site-packages\django\core\handlers\base.py", line 149, in get_response
    response = self.process_exception_by_middleware(e, request)
  File "E:\Education\GitHub Projects\PhDPortal\env\lib\site-packages\django\core\handlers\base.py", line 147, in get_response
    response = wrapped_callback(request, *callback_args, **callback_kwargs)
  File "E:\Education\GitHub Projects\PhDPortal\env\lib\site-packages\django\contrib\auth\decorators.py", line 23, in _wrapped_view
    return view_func(request, *args, **kwargs)
  File "E:\Education\GitHub Projects\PhDPortal\app\guide_views.py", line 1015, in guide_feedback_reports
    report['referee'] = referee.referee.id
  File "E:\Education\GitHub Projects\PhDPortal\env\lib\site-packages\django\db\models\fields\related_descriptors.py", line 169, in __get__
    rel_obj = qs.get()
  File "E:\Education\GitHub Projects\PhDPortal\env\lib\site-packages\django\db\models\query.py", line 381, in get
    num = len(clone)
  File "E:\Education\GitHub Projects\PhDPortal\env\lib\site-packages\django\db\models\query.py", line 240, in __len__
    self._fetch_all()
  File "E:\Education\GitHub Projects\PhDPortal\env\lib\site-packages\django\db\models\query.py", line 1074, in _fetch_all
    self._result_cache = list(self.iterator())
  File "E:\Education\GitHub Projects\PhDPortal\env\lib\site-packages\django\db\models\query.py", line 52, in __iter__
    results = compiler.execute_sql()
  File "E:\Education\GitHub Projects\PhDPortal\env\lib\site-packages\django\db\models\sql\compiler.py", line 852, in execute_sql
    cursor.execute(sql, params)
  File "E:\Education\GitHub Projects\PhDPortal\env\lib\site-packages\django\db\backends\utils.py", line 79, in execute
    return super(CursorDebugWrapper, self).execute(sql, params)
  File "E:\Education\GitHub Projects\PhDPortal\env\lib\site-packages\django\db\backends\utils.py", line 64, in execute
    return self.cursor.execute(sql, params)
  File "E:\Education\GitHub Projects\PhDPortal\env\lib\site-packages\django\db\utils.py", line 95, in __exit__
    six.reraise(dj_exc_type, dj_exc_value, traceback)
  File "E:\Education\GitHub Projects\PhDPortal\env\lib\site-packages\django\utils\six.py", line 685, in reraise
    raise value.with_traceback(tb)
  File "E:\Education\GitHub Projects\PhDPortal\env\lib\site-packages\django\db\backends\utils.py", line 64, in execute
    return self.cursor.execute(sql, params)
  File "E:\Education\GitHub Projects\PhDPortal\env\lib\site-packages\django\db\backends\sqlite3\base.py", line 323, in execute
    return Database.Cursor.execute(self, query, params)
django.db.utils.OperationalError: no such column: app_referee.added_by_id
2017-04-19 19:50:23 - ERROR - base:handle_uncaught_exception:284 - Internal Server Error: /guide/feedback/reports/
Traceback (most recent call last):
  File "E:\Education\GitHub Projects\PhDPortal\env\lib\site-packages\django\db\models\fields\related_descriptors.py", line 160, in __get__
    rel_obj = getattr(instance, self.cache_name)
AttributeError: 'PanelMember' object has no attribute '_referee_cache'

During handling of the above exception, another exception occurred:

Traceback (most recent call last):
  File "E:\Education\GitHub Projects\PhDPortal\env\lib\site-packages\django\db\backends\utils.py", line 64, in execute
    return self.cursor.execute(sql, params)
  File "E:\Education\GitHub Projects\PhDPortal\env\lib\site-packages\django\db\backends\sqlite3\base.py", line 323, in execute
    return Database.Cursor.execute(self, query, params)
sqlite3.OperationalError: no such column: app_referee.added_by_id

The above exception was the direct cause of the following exception:

Traceback (most recent call last):
  File "E:\Education\GitHub Projects\PhDPortal\env\lib\site-packages\django\core\handlers\base.py", line 149, in get_response
    response = self.process_exception_by_middleware(e, request)
  File "E:\Education\GitHub Projects\PhDPortal\env\lib\site-packages\django\core\handlers\base.py", line 147, in get_response
    response = wrapped_callback(request, *callback_args, **callback_kwargs)
  File "E:\Education\GitHub Projects\PhDPortal\env\lib\site-packages\django\contrib\auth\decorators.py", line 23, in _wrapped_view
    return view_func(request, *args, **kwargs)
  File "E:\Education\GitHub Projects\PhDPortal\app\guide_views.py", line 1015, in guide_feedback_reports
    report['referee'] = referee.referee.id
  File "E:\Education\GitHub Projects\PhDPortal\env\lib\site-packages\django\db\models\fields\related_descriptors.py", line 169, in __get__
    rel_obj = qs.get()
  File "E:\Education\GitHub Projects\PhDPortal\env\lib\site-packages\django\db\models\query.py", line 381, in get
    num = len(clone)
  File "E:\Education\GitHub Projects\PhDPortal\env\lib\site-packages\django\db\models\query.py", line 240, in __len__
    self._fetch_all()
  File "E:\Education\GitHub Projects\PhDPortal\env\lib\site-packages\django\db\models\query.py", line 1074, in _fetch_all
    self._result_cache = list(self.iterator())
  File "E:\Education\GitHub Projects\PhDPortal\env\lib\site-packages\django\db\models\query.py", line 52, in __iter__
    results = compiler.execute_sql()
  File "E:\Education\GitHub Projects\PhDPortal\env\lib\site-packages\django\db\models\sql\compiler.py", line 852, in execute_sql
    cursor.execute(sql, params)
  File "E:\Education\GitHub Projects\PhDPortal\env\lib\site-packages\django\db\backends\utils.py", line 79, in execute
    return super(CursorDebugWrapper, self).execute(sql, params)
  File "E:\Education\GitHub Projects\PhDPortal\env\lib\site-packages\django\db\backends\utils.py", line 64, in execute
    return self.cursor.execute(sql, params)
  File "E:\Education\GitHub Projects\PhDPortal\env\lib\site-packages\django\db\utils.py", line 95, in __exit__
    six.reraise(dj_exc_type, dj_exc_value, traceback)
  File "E:\Education\GitHub Projects\PhDPortal\env\lib\site-packages\django\utils\six.py", line 685, in reraise
    raise value.with_traceback(tb)
  File "E:\Education\GitHub Projects\PhDPortal\env\lib\site-packages\django\db\backends\utils.py", line 64, in execute
    return self.cursor.execute(sql, params)
  File "E:\Education\GitHub Projects\PhDPortal\env\lib\site-packages\django\db\backends\sqlite3\base.py", line 323, in execute
    return Database.Cursor.execute(self, query, params)
django.db.utils.OperationalError: no such column: app_referee.added_by_id
2017-04-19 19:55:46 - ERROR - base:handle_uncaught_exception:284 - Internal Server Error: /guide/panel/referees/foreign/
Traceback (most recent call last):
  File "E:\Education\GitHub Projects\PhDPortal\env\lib\site-packages\django\db\backends\utils.py", line 64, in execute
    return self.cursor.execute(sql, params)
  File "E:\Education\GitHub Projects\PhDPortal\env\lib\site-packages\django\db\backends\sqlite3\base.py", line 323, in execute
    return Database.Cursor.execute(self, query, params)
sqlite3.OperationalError: no such column: app_referee.added_by_id

The above exception was the direct cause of the following exception:

Traceback (most recent call last):
  File "E:\Education\GitHub Projects\PhDPortal\env\lib\site-packages\django\core\handlers\base.py", line 149, in get_response
    response = self.process_exception_by_middleware(e, request)
  File "E:\Education\GitHub Projects\PhDPortal\env\lib\site-packages\django\core\handlers\base.py", line 147, in get_response
    response = wrapped_callback(request, *callback_args, **callback_kwargs)
  File "E:\Education\GitHub Projects\PhDPortal\env\lib\site-packages\django\contrib\auth\decorators.py", line 23, in _wrapped_view
    return view_func(request, *args, **kwargs)
  File "E:\Education\GitHub Projects\PhDPortal\app\guide_views.py", line 640, in guide_get_foreign_referee_details
    return HttpResponse(json.dumps(_get_referee_details(name, 'F')), content_type = 'application/json')
  File "E:\Education\GitHub Projects\PhDPortal\app\guide_views.py", line 618, in _get_referee_details
    for referee in referees:
  File "E:\Education\GitHub Projects\PhDPortal\env\lib\site-packages\django\db\models\query.py", line 258, in __iter__
    self._fetch_all()
  File "E:\Education\GitHub Projects\PhDPortal\env\lib\site-packages\django\db\models\query.py", line 1074, in _fetch_all
    self._result_cache = list(self.iterator())
  File "E:\Education\GitHub Projects\PhDPortal\env\lib\site-packages\django\db\models\query.py", line 52, in __iter__
    results = compiler.execute_sql()
  File "E:\Education\GitHub Projects\PhDPortal\env\lib\site-packages\django\db\models\sql\compiler.py", line 852, in execute_sql
    cursor.execute(sql, params)
  File "E:\Education\GitHub Projects\PhDPortal\env\lib\site-packages\django\db\backends\utils.py", line 79, in execute
    return super(CursorDebugWrapper, self).execute(sql, params)
  File "E:\Education\GitHub Projects\PhDPortal\env\lib\site-packages\django\db\backends\utils.py", line 64, in execute
    return self.cursor.execute(sql, params)
  File "E:\Education\GitHub Projects\PhDPortal\env\lib\site-packages\django\db\utils.py", line 95, in __exit__
    six.reraise(dj_exc_type, dj_exc_value, traceback)
  File "E:\Education\GitHub Projects\PhDPortal\env\lib\site-packages\django\utils\six.py", line 685, in reraise
    raise value.with_traceback(tb)
  File "E:\Education\GitHub Projects\PhDPortal\env\lib\site-packages\django\db\backends\utils.py", line 64, in execute
    return self.cursor.execute(sql, params)
  File "E:\Education\GitHub Projects\PhDPortal\env\lib\site-packages\django\db\backends\sqlite3\base.py", line 323, in execute
    return Database.Cursor.execute(self, query, params)
django.db.utils.OperationalError: no such column: app_referee.added_by_id
2017-04-19 19:55:47 - ERROR - base:handle_uncaught_exception:284 - Internal Server Error: /guide/panel/referees/foreign/
Traceback (most recent call last):
  File "E:\Education\GitHub Projects\PhDPortal\env\lib\site-packages\django\db\backends\utils.py", line 64, in execute
    return self.cursor.execute(sql, params)
  File "E:\Education\GitHub Projects\PhDPortal\env\lib\site-packages\django\db\backends\sqlite3\base.py", line 323, in execute
    return Database.Cursor.execute(self, query, params)
sqlite3.OperationalError: no such column: app_referee.added_by_id

The above exception was the direct cause of the following exception:

Traceback (most recent call last):
  File "E:\Education\GitHub Projects\PhDPortal\env\lib\site-packages\django\core\handlers\base.py", line 149, in get_response
    response = self.process_exception_by_middleware(e, request)
  File "E:\Education\GitHub Projects\PhDPortal\env\lib\site-packages\django\core\handlers\base.py", line 147, in get_response
    response = wrapped_callback(request, *callback_args, **callback_kwargs)
  File "E:\Education\GitHub Projects\PhDPortal\env\lib\site-packages\django\contrib\auth\decorators.py", line 23, in _wrapped_view
    return view_func(request, *args, **kwargs)
  File "E:\Education\GitHub Projects\PhDPortal\app\guide_views.py", line 640, in guide_get_foreign_referee_details
    return HttpResponse(json.dumps(_get_referee_details(name, 'F')), content_type = 'application/json')
  File "E:\Education\GitHub Projects\PhDPortal\app\guide_views.py", line 618, in _get_referee_details
    for referee in referees:
  File "E:\Education\GitHub Projects\PhDPortal\env\lib\site-packages\django\db\models\query.py", line 258, in __iter__
    self._fetch_all()
  File "E:\Education\GitHub Projects\PhDPortal\env\lib\site-packages\django\db\models\query.py", line 1074, in _fetch_all
    self._result_cache = list(self.iterator())
  File "E:\Education\GitHub Projects\PhDPortal\env\lib\site-packages\django\db\models\query.py", line 52, in __iter__
    results = compiler.execute_sql()
  File "E:\Education\GitHub Projects\PhDPortal\env\lib\site-packages\django\db\models\sql\compiler.py", line 852, in execute_sql
    cursor.execute(sql, params)
  File "E:\Education\GitHub Projects\PhDPortal\env\lib\site-packages\django\db\backends\utils.py", line 79, in execute
    return super(CursorDebugWrapper, self).execute(sql, params)
  File "E:\Education\GitHub Projects\PhDPortal\env\lib\site-packages\django\db\backends\utils.py", line 64, in execute
    return self.cursor.execute(sql, params)
  File "E:\Education\GitHub Projects\PhDPortal\env\lib\site-packages\django\db\utils.py", line 95, in __exit__
    six.reraise(dj_exc_type, dj_exc_value, traceback)
  File "E:\Education\GitHub Projects\PhDPortal\env\lib\site-packages\django\utils\six.py", line 685, in reraise
    raise value.with_traceback(tb)
  File "E:\Education\GitHub Projects\PhDPortal\env\lib\site-packages\django\db\backends\utils.py", line 64, in execute
    return self.cursor.execute(sql, params)
  File "E:\Education\GitHub Projects\PhDPortal\env\lib\site-packages\django\db\backends\sqlite3\base.py", line 323, in execute
    return Database.Cursor.execute(self, query, params)
django.db.utils.OperationalError: no such column: app_referee.added_by_id
2017-04-19 19:55:48 - ERROR - base:handle_uncaught_exception:284 - Internal Server Error: /guide/panel/referees/foreign/
Traceback (most recent call last):
  File "E:\Education\GitHub Projects\PhDPortal\env\lib\site-packages\django\db\backends\utils.py", line 64, in execute
    return self.cursor.execute(sql, params)
  File "E:\Education\GitHub Projects\PhDPortal\env\lib\site-packages\django\db\backends\sqlite3\base.py", line 323, in execute
    return Database.Cursor.execute(self, query, params)
sqlite3.OperationalError: no such column: app_referee.added_by_id

The above exception was the direct cause of the following exception:

Traceback (most recent call last):
  File "E:\Education\GitHub Projects\PhDPortal\env\lib\site-packages\django\core\handlers\base.py", line 149, in get_response
    response = self.process_exception_by_middleware(e, request)
  File "E:\Education\GitHub Projects\PhDPortal\env\lib\site-packages\django\core\handlers\base.py", line 147, in get_response
    response = wrapped_callback(request, *callback_args, **callback_kwargs)
  File "E:\Education\GitHub Projects\PhDPortal\env\lib\site-packages\django\contrib\auth\decorators.py", line 23, in _wrapped_view
    return view_func(request, *args, **kwargs)
  File "E:\Education\GitHub Projects\PhDPortal\app\guide_views.py", line 640, in guide_get_foreign_referee_details
    return HttpResponse(json.dumps(_get_referee_details(name, 'F')), content_type = 'application/json')
  File "E:\Education\GitHub Projects\PhDPortal\app\guide_views.py", line 618, in _get_referee_details
    for referee in referees:
  File "E:\Education\GitHub Projects\PhDPortal\env\lib\site-packages\django\db\models\query.py", line 258, in __iter__
    self._fetch_all()
  File "E:\Education\GitHub Projects\PhDPortal\env\lib\site-packages\django\db\models\query.py", line 1074, in _fetch_all
    self._result_cache = list(self.iterator())
  File "E:\Education\GitHub Projects\PhDPortal\env\lib\site-packages\django\db\models\query.py", line 52, in __iter__
    results = compiler.execute_sql()
  File "E:\Education\GitHub Projects\PhDPortal\env\lib\site-packages\django\db\models\sql\compiler.py", line 852, in execute_sql
    cursor.execute(sql, params)
  File "E:\Education\GitHub Projects\PhDPortal\env\lib\site-packages\django\db\backends\utils.py", line 79, in execute
    return super(CursorDebugWrapper, self).execute(sql, params)
  File "E:\Education\GitHub Projects\PhDPortal\env\lib\site-packages\django\db\backends\utils.py", line 64, in execute
    return self.cursor.execute(sql, params)
  File "E:\Education\GitHub Projects\PhDPortal\env\lib\site-packages\django\db\utils.py", line 95, in __exit__
    six.reraise(dj_exc_type, dj_exc_value, traceback)
  File "E:\Education\GitHub Projects\PhDPortal\env\lib\site-packages\django\utils\six.py", line 685, in reraise
    raise value.with_traceback(tb)
  File "E:\Education\GitHub Projects\PhDPortal\env\lib\site-packages\django\db\backends\utils.py", line 64, in execute
    return self.cursor.execute(sql, params)
  File "E:\Education\GitHub Projects\PhDPortal\env\lib\site-packages\django\db\backends\sqlite3\base.py", line 323, in execute
    return Database.Cursor.execute(self, query, params)
django.db.utils.OperationalError: no such column: app_referee.added_by_id
2017-04-19 19:55:55 - ERROR - base:handle_uncaught_exception:284 - Internal Server Error: /guide/panel/referees/foreign/
Traceback (most recent call last):
  File "E:\Education\GitHub Projects\PhDPortal\env\lib\site-packages\django\db\backends\utils.py", line 64, in execute
    return self.cursor.execute(sql, params)
  File "E:\Education\GitHub Projects\PhDPortal\env\lib\site-packages\django\db\backends\sqlite3\base.py", line 323, in execute
    return Database.Cursor.execute(self, query, params)
sqlite3.OperationalError: no such column: app_referee.added_by_id

The above exception was the direct cause of the following exception:

Traceback (most recent call last):
  File "E:\Education\GitHub Projects\PhDPortal\env\lib\site-packages\django\core\handlers\base.py", line 149, in get_response
    response = self.process_exception_by_middleware(e, request)
  File "E:\Education\GitHub Projects\PhDPortal\env\lib\site-packages\django\core\handlers\base.py", line 147, in get_response
    response = wrapped_callback(request, *callback_args, **callback_kwargs)
  File "E:\Education\GitHub Projects\PhDPortal\env\lib\site-packages\django\contrib\auth\decorators.py", line 23, in _wrapped_view
    return view_func(request, *args, **kwargs)
  File "E:\Education\GitHub Projects\PhDPortal\app\guide_views.py", line 640, in guide_get_foreign_referee_details
    return HttpResponse(json.dumps(_get_referee_details(name, 'F')), content_type = 'application/json')
  File "E:\Education\GitHub Projects\PhDPortal\app\guide_views.py", line 618, in _get_referee_details
    for referee in referees:
  File "E:\Education\GitHub Projects\PhDPortal\env\lib\site-packages\django\db\models\query.py", line 258, in __iter__
    self._fetch_all()
  File "E:\Education\GitHub Projects\PhDPortal\env\lib\site-packages\django\db\models\query.py", line 1074, in _fetch_all
    self._result_cache = list(self.iterator())
  File "E:\Education\GitHub Projects\PhDPortal\env\lib\site-packages\django\db\models\query.py", line 52, in __iter__
    results = compiler.execute_sql()
  File "E:\Education\GitHub Projects\PhDPortal\env\lib\site-packages\django\db\models\sql\compiler.py", line 852, in execute_sql
    cursor.execute(sql, params)
  File "E:\Education\GitHub Projects\PhDPortal\env\lib\site-packages\django\db\backends\utils.py", line 79, in execute
    return super(CursorDebugWrapper, self).execute(sql, params)
  File "E:\Education\GitHub Projects\PhDPortal\env\lib\site-packages\django\db\backends\utils.py", line 64, in execute
    return self.cursor.execute(sql, params)
  File "E:\Education\GitHub Projects\PhDPortal\env\lib\site-packages\django\db\utils.py", line 95, in __exit__
    six.reraise(dj_exc_type, dj_exc_value, traceback)
  File "E:\Education\GitHub Projects\PhDPortal\env\lib\site-packages\django\utils\six.py", line 685, in reraise
    raise value.with_traceback(tb)
  File "E:\Education\GitHub Projects\PhDPortal\env\lib\site-packages\django\db\backends\utils.py", line 64, in execute
    return self.cursor.execute(sql, params)
  File "E:\Education\GitHub Projects\PhDPortal\env\lib\site-packages\django\db\backends\sqlite3\base.py", line 323, in execute
    return Database.Cursor.execute(self, query, params)
django.db.utils.OperationalError: no such column: app_referee.added_by_id
2017-04-19 19:59:36 - ERROR - base:handle_uncaught_exception:284 - Internal Server Error: /guide/panel/referees/foreign/
Traceback (most recent call last):
  File "E:\Education\GitHub Projects\PhDPortal\env\lib\site-packages\django\db\backends\utils.py", line 64, in execute
    return self.cursor.execute(sql, params)
  File "E:\Education\GitHub Projects\PhDPortal\env\lib\site-packages\django\db\backends\sqlite3\base.py", line 323, in execute
    return Database.Cursor.execute(self, query, params)
sqlite3.OperationalError: no such column: app_referee.added_by_id

The above exception was the direct cause of the following exception:

Traceback (most recent call last):
  File "E:\Education\GitHub Projects\PhDPortal\env\lib\site-packages\django\core\handlers\base.py", line 149, in get_response
    response = self.process_exception_by_middleware(e, request)
  File "E:\Education\GitHub Projects\PhDPortal\env\lib\site-packages\django\core\handlers\base.py", line 147, in get_response
    response = wrapped_callback(request, *callback_args, **callback_kwargs)
  File "E:\Education\GitHub Projects\PhDPortal\env\lib\site-packages\django\contrib\auth\decorators.py", line 23, in _wrapped_view
    return view_func(request, *args, **kwargs)
  File "E:\Education\GitHub Projects\PhDPortal\app\guide_views.py", line 640, in guide_get_foreign_referee_details
    return HttpResponse(json.dumps(_get_referee_details(name, 'F')), content_type = 'application/json')
  File "E:\Education\GitHub Projects\PhDPortal\app\guide_views.py", line 618, in _get_referee_details
    for referee in referees:
  File "E:\Education\GitHub Projects\PhDPortal\env\lib\site-packages\django\db\models\query.py", line 258, in __iter__
    self._fetch_all()
  File "E:\Education\GitHub Projects\PhDPortal\env\lib\site-packages\django\db\models\query.py", line 1074, in _fetch_all
    self._result_cache = list(self.iterator())
  File "E:\Education\GitHub Projects\PhDPortal\env\lib\site-packages\django\db\models\query.py", line 52, in __iter__
    results = compiler.execute_sql()
  File "E:\Education\GitHub Projects\PhDPortal\env\lib\site-packages\django\db\models\sql\compiler.py", line 852, in execute_sql
    cursor.execute(sql, params)
  File "E:\Education\GitHub Projects\PhDPortal\env\lib\site-packages\django\db\backends\utils.py", line 79, in execute
    return super(CursorDebugWrapper, self).execute(sql, params)
  File "E:\Education\GitHub Projects\PhDPortal\env\lib\site-packages\django\db\backends\utils.py", line 64, in execute
    return self.cursor.execute(sql, params)
  File "E:\Education\GitHub Projects\PhDPortal\env\lib\site-packages\django\db\utils.py", line 95, in __exit__
    six.reraise(dj_exc_type, dj_exc_value, traceback)
  File "E:\Education\GitHub Projects\PhDPortal\env\lib\site-packages\django\utils\six.py", line 685, in reraise
    raise value.with_traceback(tb)
  File "E:\Education\GitHub Projects\PhDPortal\env\lib\site-packages\django\db\backends\utils.py", line 64, in execute
    return self.cursor.execute(sql, params)
  File "E:\Education\GitHub Projects\PhDPortal\env\lib\site-packages\django\db\backends\sqlite3\base.py", line 323, in execute
    return Database.Cursor.execute(self, query, params)
django.db.utils.OperationalError: no such column: app_referee.added_by_id
2017-04-19 20:01:00 - INFO - views:login:414 - User pavan successfully authenticated
2017-04-19 20:04:04 - ERROR - base:handle_uncaught_exception:284 - Internal Server Error: /guide/panel/referees/foreign/
Traceback (most recent call last):
  File "E:\Education\GitHub Projects\PhDPortal\env\lib\site-packages\django\utils\datastructures.py", line 83, in __getitem__
    list_ = super(MultiValueDict, self).__getitem__(key)
KeyError: 'term'

During handling of the above exception, another exception occurred:

Traceback (most recent call last):
  File "E:\Education\GitHub Projects\PhDPortal\env\lib\site-packages\django\core\handlers\base.py", line 149, in get_response
    response = self.process_exception_by_middleware(e, request)
  File "E:\Education\GitHub Projects\PhDPortal\env\lib\site-packages\django\core\handlers\base.py", line 147, in get_response
    response = wrapped_callback(request, *callback_args, **callback_kwargs)
  File "E:\Education\GitHub Projects\PhDPortal\env\lib\site-packages\django\contrib\auth\decorators.py", line 23, in _wrapped_view
    return view_func(request, *args, **kwargs)
  File "E:\Education\GitHub Projects\PhDPortal\app\guide_views.py", line 638, in guide_get_foreign_referee_details
    name = request.GET['term']
  File "E:\Education\GitHub Projects\PhDPortal\env\lib\site-packages\django\utils\datastructures.py", line 85, in __getitem__
    raise MultiValueDictKeyError(repr(key))
django.utils.datastructures.MultiValueDictKeyError: "'term'"
2017-04-19 20:04:05 - ERROR - base:handle_uncaught_exception:284 - Internal Server Error: /guide/panel/referees/foreign/
Traceback (most recent call last):
  File "E:\Education\GitHub Projects\PhDPortal\env\lib\site-packages\django\utils\datastructures.py", line 83, in __getitem__
    list_ = super(MultiValueDict, self).__getitem__(key)
KeyError: 'term'

During handling of the above exception, another exception occurred:

Traceback (most recent call last):
  File "E:\Education\GitHub Projects\PhDPortal\env\lib\site-packages\django\core\handlers\base.py", line 149, in get_response
    response = self.process_exception_by_middleware(e, request)
  File "E:\Education\GitHub Projects\PhDPortal\env\lib\site-packages\django\core\handlers\base.py", line 147, in get_response
    response = wrapped_callback(request, *callback_args, **callback_kwargs)
  File "E:\Education\GitHub Projects\PhDPortal\env\lib\site-packages\django\contrib\auth\decorators.py", line 23, in _wrapped_view
    return view_func(request, *args, **kwargs)
  File "E:\Education\GitHub Projects\PhDPortal\app\guide_views.py", line 638, in guide_get_foreign_referee_details
    name = request.GET['term']
  File "E:\Education\GitHub Projects\PhDPortal\env\lib\site-packages\django\utils\datastructures.py", line 85, in __getitem__
    raise MultiValueDictKeyError(repr(key))
django.utils.datastructures.MultiValueDictKeyError: "'term'"
2017-04-19 20:04:06 - ERROR - base:handle_uncaught_exception:284 - Internal Server Error: /guide/panel/referees/foreign/
Traceback (most recent call last):
  File "E:\Education\GitHub Projects\PhDPortal\env\lib\site-packages\django\utils\datastructures.py", line 83, in __getitem__
    list_ = super(MultiValueDict, self).__getitem__(key)
KeyError: 'term'

During handling of the above exception, another exception occurred:

Traceback (most recent call last):
  File "E:\Education\GitHub Projects\PhDPortal\env\lib\site-packages\django\core\handlers\base.py", line 149, in get_response
    response = self.process_exception_by_middleware(e, request)
  File "E:\Education\GitHub Projects\PhDPortal\env\lib\site-packages\django\core\handlers\base.py", line 147, in get_response
    response = wrapped_callback(request, *callback_args, **callback_kwargs)
  File "E:\Education\GitHub Projects\PhDPortal\env\lib\site-packages\django\contrib\auth\decorators.py", line 23, in _wrapped_view
    return view_func(request, *args, **kwargs)
  File "E:\Education\GitHub Projects\PhDPortal\app\guide_views.py", line 638, in guide_get_foreign_referee_details
    name = request.GET['term']
  File "E:\Education\GitHub Projects\PhDPortal\env\lib\site-packages\django\utils\datastructures.py", line 85, in __getitem__
    raise MultiValueDictKeyError(repr(key))
django.utils.datastructures.MultiValueDictKeyError: "'term'"
2017-04-19 20:04:07 - ERROR - base:handle_uncaught_exception:284 - Internal Server Error: /guide/panel/referees/foreign/
Traceback (most recent call last):
  File "E:\Education\GitHub Projects\PhDPortal\env\lib\site-packages\django\utils\datastructures.py", line 83, in __getitem__
    list_ = super(MultiValueDict, self).__getitem__(key)
KeyError: 'term'

During handling of the above exception, another exception occurred:

Traceback (most recent call last):
  File "E:\Education\GitHub Projects\PhDPortal\env\lib\site-packages\django\core\handlers\base.py", line 149, in get_response
    response = self.process_exception_by_middleware(e, request)
  File "E:\Education\GitHub Projects\PhDPortal\env\lib\site-packages\django\core\handlers\base.py", line 147, in get_response
    response = wrapped_callback(request, *callback_args, **callback_kwargs)
  File "E:\Education\GitHub Projects\PhDPortal\env\lib\site-packages\django\contrib\auth\decorators.py", line 23, in _wrapped_view
    return view_func(request, *args, **kwargs)
  File "E:\Education\GitHub Projects\PhDPortal\app\guide_views.py", line 638, in guide_get_foreign_referee_details
    name = request.GET['term']
  File "E:\Education\GitHub Projects\PhDPortal\env\lib\site-packages\django\utils\datastructures.py", line 85, in __getitem__
    raise MultiValueDictKeyError(repr(key))
django.utils.datastructures.MultiValueDictKeyError: "'term'"
2017-04-19 20:04:07 - ERROR - base:handle_uncaught_exception:284 - Internal Server Error: /guide/panel/referees/foreign/
Traceback (most recent call last):
  File "E:\Education\GitHub Projects\PhDPortal\env\lib\site-packages\django\utils\datastructures.py", line 83, in __getitem__
    list_ = super(MultiValueDict, self).__getitem__(key)
KeyError: 'term'

During handling of the above exception, another exception occurred:

Traceback (most recent call last):
  File "E:\Education\GitHub Projects\PhDPortal\env\lib\site-packages\django\core\handlers\base.py", line 149, in get_response
    response = self.process_exception_by_middleware(e, request)
  File "E:\Education\GitHub Projects\PhDPortal\env\lib\site-packages\django\core\handlers\base.py", line 147, in get_response
    response = wrapped_callback(request, *callback_args, **callback_kwargs)
  File "E:\Education\GitHub Projects\PhDPortal\env\lib\site-packages\django\contrib\auth\decorators.py", line 23, in _wrapped_view
    return view_func(request, *args, **kwargs)
  File "E:\Education\GitHub Projects\PhDPortal\app\guide_views.py", line 638, in guide_get_foreign_referee_details
    name = request.GET['term']
  File "E:\Education\GitHub Projects\PhDPortal\env\lib\site-packages\django\utils\datastructures.py", line 85, in __getitem__
    raise MultiValueDictKeyError(repr(key))
django.utils.datastructures.MultiValueDictKeyError: "'term'"
2017-04-19 20:04:37 - ERROR - base:handle_uncaught_exception:284 - Internal Server Error: /guide/panel/referees/foreign/
Traceback (most recent call last):
  File "E:\Education\GitHub Projects\PhDPortal\env\lib\site-packages\django\utils\datastructures.py", line 83, in __getitem__
    list_ = super(MultiValueDict, self).__getitem__(key)
KeyError: 'term'

During handling of the above exception, another exception occurred:

Traceback (most recent call last):
  File "E:\Education\GitHub Projects\PhDPortal\env\lib\site-packages\django\core\handlers\base.py", line 149, in get_response
    response = self.process_exception_by_middleware(e, request)
  File "E:\Education\GitHub Projects\PhDPortal\env\lib\site-packages\django\core\handlers\base.py", line 147, in get_response
    response = wrapped_callback(request, *callback_args, **callback_kwargs)
  File "E:\Education\GitHub Projects\PhDPortal\env\lib\site-packages\django\contrib\auth\decorators.py", line 23, in _wrapped_view
    return view_func(request, *args, **kwargs)
  File "E:\Education\GitHub Projects\PhDPortal\app\guide_views.py", line 638, in guide_get_foreign_referee_details
    name = request.GET['term']
  File "E:\Education\GitHub Projects\PhDPortal\env\lib\site-packages\django\utils\datastructures.py", line 85, in __getitem__
    raise MultiValueDictKeyError(repr(key))
django.utils.datastructures.MultiValueDictKeyError: "'term'"
2017-04-19 20:04:37 - ERROR - base:handle_uncaught_exception:284 - Internal Server Error: /guide/panel/referees/foreign/
Traceback (most recent call last):
  File "E:\Education\GitHub Projects\PhDPortal\env\lib\site-packages\django\utils\datastructures.py", line 83, in __getitem__
    list_ = super(MultiValueDict, self).__getitem__(key)
KeyError: 'term'

During handling of the above exception, another exception occurred:

Traceback (most recent call last):
  File "E:\Education\GitHub Projects\PhDPortal\env\lib\site-packages\django\core\handlers\base.py", line 149, in get_response
    response = self.process_exception_by_middleware(e, request)
  File "E:\Education\GitHub Projects\PhDPortal\env\lib\site-packages\django\core\handlers\base.py", line 147, in get_response
    response = wrapped_callback(request, *callback_args, **callback_kwargs)
  File "E:\Education\GitHub Projects\PhDPortal\env\lib\site-packages\django\contrib\auth\decorators.py", line 23, in _wrapped_view
    return view_func(request, *args, **kwargs)
  File "E:\Education\GitHub Projects\PhDPortal\app\guide_views.py", line 638, in guide_get_foreign_referee_details
    name = request.GET['term']
  File "E:\Education\GitHub Projects\PhDPortal\env\lib\site-packages\django\utils\datastructures.py", line 85, in __getitem__
    raise MultiValueDictKeyError(repr(key))
django.utils.datastructures.MultiValueDictKeyError: "'term'"
2017-04-19 20:04:37 - ERROR - base:handle_uncaught_exception:284 - Internal Server Error: /guide/panel/referees/foreign/
Traceback (most recent call last):
  File "E:\Education\GitHub Projects\PhDPortal\env\lib\site-packages\django\utils\datastructures.py", line 83, in __getitem__
    list_ = super(MultiValueDict, self).__getitem__(key)
KeyError: 'term'

During handling of the above exception, another exception occurred:

Traceback (most recent call last):
  File "E:\Education\GitHub Projects\PhDPortal\env\lib\site-packages\django\core\handlers\base.py", line 149, in get_response
    response = self.process_exception_by_middleware(e, request)
  File "E:\Education\GitHub Projects\PhDPortal\env\lib\site-packages\django\core\handlers\base.py", line 147, in get_response
    response = wrapped_callback(request, *callback_args, **callback_kwargs)
  File "E:\Education\GitHub Projects\PhDPortal\env\lib\site-packages\django\contrib\auth\decorators.py", line 23, in _wrapped_view
    return view_func(request, *args, **kwargs)
  File "E:\Education\GitHub Projects\PhDPortal\app\guide_views.py", line 638, in guide_get_foreign_referee_details
    name = request.GET['term']
  File "E:\Education\GitHub Projects\PhDPortal\env\lib\site-packages\django\utils\datastructures.py", line 85, in __getitem__
    raise MultiValueDictKeyError(repr(key))
django.utils.datastructures.MultiValueDictKeyError: "'term'"
2017-04-19 20:04:57 - ERROR - base:handle_uncaught_exception:284 - Internal Server Error: /guide/panel/referees/foreign/
Traceback (most recent call last):
  File "E:\Education\GitHub Projects\PhDPortal\env\lib\site-packages\django\utils\datastructures.py", line 83, in __getitem__
    list_ = super(MultiValueDict, self).__getitem__(key)
KeyError: 'term'

During handling of the above exception, another exception occurred:

Traceback (most recent call last):
  File "E:\Education\GitHub Projects\PhDPortal\env\lib\site-packages\django\core\handlers\base.py", line 149, in get_response
    response = self.process_exception_by_middleware(e, request)
  File "E:\Education\GitHub Projects\PhDPortal\env\lib\site-packages\django\core\handlers\base.py", line 147, in get_response
    response = wrapped_callback(request, *callback_args, **callback_kwargs)
  File "E:\Education\GitHub Projects\PhDPortal\env\lib\site-packages\django\contrib\auth\decorators.py", line 23, in _wrapped_view
    return view_func(request, *args, **kwargs)
  File "E:\Education\GitHub Projects\PhDPortal\app\guide_views.py", line 638, in guide_get_foreign_referee_details
    name = request.GET['term']
  File "E:\Education\GitHub Projects\PhDPortal\env\lib\site-packages\django\utils\datastructures.py", line 85, in __getitem__
    raise MultiValueDictKeyError(repr(key))
django.utils.datastructures.MultiValueDictKeyError: "'term'"
2017-04-19 20:04:58 - ERROR - base:handle_uncaught_exception:284 - Internal Server Error: /guide/panel/referees/foreign/
Traceback (most recent call last):
  File "E:\Education\GitHub Projects\PhDPortal\env\lib\site-packages\django\utils\datastructures.py", line 83, in __getitem__
    list_ = super(MultiValueDict, self).__getitem__(key)
KeyError: 'term'

During handling of the above exception, another exception occurred:

Traceback (most recent call last):
  File "E:\Education\GitHub Projects\PhDPortal\env\lib\site-packages\django\core\handlers\base.py", line 149, in get_response
    response = self.process_exception_by_middleware(e, request)
  File "E:\Education\GitHub Projects\PhDPortal\env\lib\site-packages\django\core\handlers\base.py", line 147, in get_response
    response = wrapped_callback(request, *callback_args, **callback_kwargs)
  File "E:\Education\GitHub Projects\PhDPortal\env\lib\site-packages\django\contrib\auth\decorators.py", line 23, in _wrapped_view
    return view_func(request, *args, **kwargs)
  File "E:\Education\GitHub Projects\PhDPortal\app\guide_views.py", line 638, in guide_get_foreign_referee_details
    name = request.GET['term']
  File "E:\Education\GitHub Projects\PhDPortal\env\lib\site-packages\django\utils\datastructures.py", line 85, in __getitem__
    raise MultiValueDictKeyError(repr(key))
django.utils.datastructures.MultiValueDictKeyError: "'term'"
2017-04-19 20:07:27 - ERROR - base:handle_uncaught_exception:284 - Internal Server Error: /guide/panel/referees/foreign/
Traceback (most recent call last):
  File "E:\Education\GitHub Projects\PhDPortal\env\lib\site-packages\django\utils\datastructures.py", line 83, in __getitem__
    list_ = super(MultiValueDict, self).__getitem__(key)
KeyError: 'term'

During handling of the above exception, another exception occurred:

Traceback (most recent call last):
  File "E:\Education\GitHub Projects\PhDPortal\env\lib\site-packages\django\core\handlers\base.py", line 149, in get_response
    response = self.process_exception_by_middleware(e, request)
  File "E:\Education\GitHub Projects\PhDPortal\env\lib\site-packages\django\core\handlers\base.py", line 147, in get_response
    response = wrapped_callback(request, *callback_args, **callback_kwargs)
  File "E:\Education\GitHub Projects\PhDPortal\env\lib\site-packages\django\contrib\auth\decorators.py", line 23, in _wrapped_view
    return view_func(request, *args, **kwargs)
  File "E:\Education\GitHub Projects\PhDPortal\app\guide_views.py", line 638, in guide_get_foreign_referee_details
    name = request.GET['term']
  File "E:\Education\GitHub Projects\PhDPortal\env\lib\site-packages\django\utils\datastructures.py", line 85, in __getitem__
    raise MultiValueDictKeyError(repr(key))
django.utils.datastructures.MultiValueDictKeyError: "'term'"
2017-04-19 20:34:36 - INFO - views:login:414 - User gcnandi successfully authenticated
2017-04-19 20:35:03 - INFO - views:logout:436 - User gcnandi successfully logged out
2017-04-19 20:35:07 - INFO - views:login:414 - User pavan successfully authenticated
2017-04-19 20:36:27 - INFO - guide_views:guide_save_panel_members:915 - 4   shanu
2017-04-19 20:36:27 - INFO - guide_views:guide_save_panel_members:915 - 2   shanu
2017-04-19 20:36:27 - INFO - guide_views:guide_save_panel_members:915 - 1   shanu
2017-04-19 20:36:27 - INFO - guide_views:guide_save_panel_members:915 - 6   shanu
2017-04-19 20:36:35 - INFO - guide_views:guide_send_panel_to_director:797 - Before_Deletion
2017-04-19 20:36:35 - INFO - guide_views:guide_send_panel_to_director:801 - After_Deletion
2017-04-19 20:36:36 - INFO - guide_views:guide_send_panel_to_director:827 - here
2017-04-19 20:36:36 - INFO - guide_views:guide_send_panel_to_director:840 - True
2017-04-19 20:36:42 - INFO - views:logout:436 - User pavan successfully logged out
2017-04-19 20:36:48 - INFO - views:login:414 - User gcnandi successfully authenticated
2017-04-19 20:58:52 - ERROR - base:handle_uncaught_exception:284 - Internal Server Error: /director/evaluate/
Traceback (most recent call last):
  File "E:\Education\GitHub Projects\PhDPortal\env\lib\site-packages\django\template\defaulttags.py", line 507, in render
    current_app=current_app)
  File "E:\Education\GitHub Projects\PhDPortal\env\lib\site-packages\django\core\urlresolvers.py", line 600, in reverse
    return force_text(iri_to_uri(resolver._reverse_with_prefix(view, prefix, *args, **kwargs)))
  File "E:\Education\GitHub Projects\PhDPortal\env\lib\site-packages\django\core\urlresolvers.py", line 508, in _reverse_with_prefix
    (lookup_view_s, args, kwargs, len(patterns), patterns))
django.core.urlresolvers.NoReverseMatch: Reverse for 'PhDPortal.director_add_panel_members' with arguments '()' and keyword arguments '{}' not found. 0 pattern(s) tried: []

During handling of the above exception, another exception occurred:

Traceback (most recent call last):
  File "E:\Education\GitHub Projects\PhDPortal\env\lib\site-packages\django\core\handlers\base.py", line 149, in get_response
    response = self.process_exception_by_middleware(e, request)
  File "E:\Education\GitHub Projects\PhDPortal\env\lib\site-packages\django\core\handlers\base.py", line 147, in get_response
    response = wrapped_callback(request, *callback_args, **callback_kwargs)
  File "E:\Education\GitHub Projects\PhDPortal\env\lib\site-packages\django\contrib\auth\decorators.py", line 23, in _wrapped_view
    return view_func(request, *args, **kwargs)
  File "E:\Education\GitHub Projects\PhDPortal\app\director_views.py", line 145, in director_submit_for_evaluation
    'all_list' : all_list
  File "E:\Education\GitHub Projects\PhDPortal\env\lib\site-packages\django\shortcuts.py", line 67, in render
    template_name, context, request=request, using=using)
  File "E:\Education\GitHub Projects\PhDPortal\env\lib\site-packages\django\template\loader.py", line 97, in render_to_string
    return template.render(context, request)
  File "E:\Education\GitHub Projects\PhDPortal\env\lib\site-packages\django\template\backends\django.py", line 95, in render
    return self.template.render(context)
  File "E:\Education\GitHub Projects\PhDPortal\env\lib\site-packages\django\template\base.py", line 206, in render
    return self._render(context)
  File "E:\Education\GitHub Projects\PhDPortal\env\lib\site-packages\django\template\base.py", line 197, in _render
    return self.nodelist.render(context)
  File "E:\Education\GitHub Projects\PhDPortal\env\lib\site-packages\django\template\base.py", line 988, in render
    bit = node.render_annotated(context)
  File "E:\Education\GitHub Projects\PhDPortal\env\lib\site-packages\django\template\base.py", line 955, in render_annotated
    return self.render(context)
  File "E:\Education\GitHub Projects\PhDPortal\env\lib\site-packages\django\template\loader_tags.py", line 173, in render
    return compiled_parent._render(context)
  File "E:\Education\GitHub Projects\PhDPortal\env\lib\site-packages\django\template\base.py", line 197, in _render
    return self.nodelist.render(context)
  File "E:\Education\GitHub Projects\PhDPortal\env\lib\site-packages\django\template\base.py", line 988, in render
    bit = node.render_annotated(context)
  File "E:\Education\GitHub Projects\PhDPortal\env\lib\site-packages\django\template\base.py", line 955, in render_annotated
    return self.render(context)
  File "E:\Education\GitHub Projects\PhDPortal\env\lib\site-packages\django\template\loader_tags.py", line 69, in render
    result = block.nodelist.render(context)
  File "E:\Education\GitHub Projects\PhDPortal\env\lib\site-packages\django\template\base.py", line 988, in render
    bit = node.render_annotated(context)
  File "E:\Education\GitHub Projects\PhDPortal\env\lib\site-packages\django\template\base.py", line 955, in render_annotated
    return self.render(context)
  File "E:\Education\GitHub Projects\PhDPortal\env\lib\site-packages\django\template\defaulttags.py", line 220, in render
    nodelist.append(node.render_annotated(context))
  File "E:\Education\GitHub Projects\PhDPortal\env\lib\site-packages\django\template\base.py", line 955, in render_annotated
    return self.render(context)
  File "E:\Education\GitHub Projects\PhDPortal\env\lib\site-packages\django\template\defaulttags.py", line 513, in render
    six.reraise(*exc_info)
  File "E:\Education\GitHub Projects\PhDPortal\env\lib\site-packages\django\utils\six.py", line 686, in reraise
    raise value
  File "E:\Education\GitHub Projects\PhDPortal\env\lib\site-packages\django\template\defaulttags.py", line 499, in render
    url = reverse(view_name, args=args, kwargs=kwargs, current_app=current_app)
  File "E:\Education\GitHub Projects\PhDPortal\env\lib\site-packages\django\core\urlresolvers.py", line 600, in reverse
    return force_text(iri_to_uri(resolver._reverse_with_prefix(view, prefix, *args, **kwargs)))
  File "E:\Education\GitHub Projects\PhDPortal\env\lib\site-packages\django\core\urlresolvers.py", line 508, in _reverse_with_prefix
    (lookup_view_s, args, kwargs, len(patterns), patterns))
django.core.urlresolvers.NoReverseMatch: Reverse for 'director_add_panel_members' with arguments '()' and keyword arguments '{}' not found. 0 pattern(s) tried: []
2017-04-19 20:59:42 - ERROR - base:handle_uncaught_exception:284 - Internal Server Error: /director/evaluate/
Traceback (most recent call last):
  File "E:\Education\GitHub Projects\PhDPortal\env\lib\site-packages\django\template\defaulttags.py", line 507, in render
    current_app=current_app)
  File "E:\Education\GitHub Projects\PhDPortal\env\lib\site-packages\django\core\urlresolvers.py", line 600, in reverse
    return force_text(iri_to_uri(resolver._reverse_with_prefix(view, prefix, *args, **kwargs)))
  File "E:\Education\GitHub Projects\PhDPortal\env\lib\site-packages\django\core\urlresolvers.py", line 508, in _reverse_with_prefix
    (lookup_view_s, args, kwargs, len(patterns), patterns))
django.core.urlresolvers.NoReverseMatch: Reverse for 'PhDPortal.director_add_panel_members' with arguments '()' and keyword arguments '{}' not found. 0 pattern(s) tried: []

During handling of the above exception, another exception occurred:

Traceback (most recent call last):
  File "E:\Education\GitHub Projects\PhDPortal\env\lib\site-packages\django\core\handlers\base.py", line 149, in get_response
    response = self.process_exception_by_middleware(e, request)
  File "E:\Education\GitHub Projects\PhDPortal\env\lib\site-packages\django\core\handlers\base.py", line 147, in get_response
    response = wrapped_callback(request, *callback_args, **callback_kwargs)
  File "E:\Education\GitHub Projects\PhDPortal\env\lib\site-packages\django\contrib\auth\decorators.py", line 23, in _wrapped_view
    return view_func(request, *args, **kwargs)
  File "E:\Education\GitHub Projects\PhDPortal\app\director_views.py", line 145, in director_submit_for_evaluation
    'all_list' : all_list
  File "E:\Education\GitHub Projects\PhDPortal\env\lib\site-packages\django\shortcuts.py", line 67, in render
    template_name, context, request=request, using=using)
  File "E:\Education\GitHub Projects\PhDPortal\env\lib\site-packages\django\template\loader.py", line 97, in render_to_string
    return template.render(context, request)
  File "E:\Education\GitHub Projects\PhDPortal\env\lib\site-packages\django\template\backends\django.py", line 95, in render
    return self.template.render(context)
  File "E:\Education\GitHub Projects\PhDPortal\env\lib\site-packages\django\template\base.py", line 206, in render
    return self._render(context)
  File "E:\Education\GitHub Projects\PhDPortal\env\lib\site-packages\django\template\base.py", line 197, in _render
    return self.nodelist.render(context)
  File "E:\Education\GitHub Projects\PhDPortal\env\lib\site-packages\django\template\base.py", line 988, in render
    bit = node.render_annotated(context)
  File "E:\Education\GitHub Projects\PhDPortal\env\lib\site-packages\django\template\base.py", line 955, in render_annotated
    return self.render(context)
  File "E:\Education\GitHub Projects\PhDPortal\env\lib\site-packages\django\template\loader_tags.py", line 173, in render
    return compiled_parent._render(context)
  File "E:\Education\GitHub Projects\PhDPortal\env\lib\site-packages\django\template\base.py", line 197, in _render
    return self.nodelist.render(context)
  File "E:\Education\GitHub Projects\PhDPortal\env\lib\site-packages\django\template\base.py", line 988, in render
    bit = node.render_annotated(context)
  File "E:\Education\GitHub Projects\PhDPortal\env\lib\site-packages\django\template\base.py", line 955, in render_annotated
    return self.render(context)
  File "E:\Education\GitHub Projects\PhDPortal\env\lib\site-packages\django\template\loader_tags.py", line 69, in render
    result = block.nodelist.render(context)
  File "E:\Education\GitHub Projects\PhDPortal\env\lib\site-packages\django\template\base.py", line 988, in render
    bit = node.render_annotated(context)
  File "E:\Education\GitHub Projects\PhDPortal\env\lib\site-packages\django\template\base.py", line 955, in render_annotated
    return self.render(context)
  File "E:\Education\GitHub Projects\PhDPortal\env\lib\site-packages\django\template\defaulttags.py", line 220, in render
    nodelist.append(node.render_annotated(context))
  File "E:\Education\GitHub Projects\PhDPortal\env\lib\site-packages\django\template\base.py", line 955, in render_annotated
    return self.render(context)
  File "E:\Education\GitHub Projects\PhDPortal\env\lib\site-packages\django\template\defaulttags.py", line 513, in render
    six.reraise(*exc_info)
  File "E:\Education\GitHub Projects\PhDPortal\env\lib\site-packages\django\utils\six.py", line 686, in reraise
    raise value
  File "E:\Education\GitHub Projects\PhDPortal\env\lib\site-packages\django\template\defaulttags.py", line 499, in render
    url = reverse(view_name, args=args, kwargs=kwargs, current_app=current_app)
  File "E:\Education\GitHub Projects\PhDPortal\env\lib\site-packages\django\core\urlresolvers.py", line 600, in reverse
    return force_text(iri_to_uri(resolver._reverse_with_prefix(view, prefix, *args, **kwargs)))
  File "E:\Education\GitHub Projects\PhDPortal\env\lib\site-packages\django\core\urlresolvers.py", line 508, in _reverse_with_prefix
    (lookup_view_s, args, kwargs, len(patterns), patterns))
django.core.urlresolvers.NoReverseMatch: Reverse for 'director_add_panel_members' with arguments '()' and keyword arguments '{}' not found. 0 pattern(s) tried: []
2017-04-19 21:00:36 - WARNING - csrf:_reject:103 - Forbidden (CSRF token missing or incorrect.): /director/panel/add/
2017-04-19 21:01:18 - WARNING - csrf:_reject:103 - Forbidden (CSRF token missing or incorrect.): /director/panel/add/
2017-04-19 21:01:39 - WARNING - csrf:_reject:103 - Forbidden (CSRF token missing or incorrect.): /director/panel/add/
2017-04-19 21:03:28 - ERROR - base:handle_uncaught_exception:284 - Internal Server Error: /director/panel/add/
Traceback (most recent call last):
  File "E:\Education\GitHub Projects\PhDPortal\env\lib\site-packages\django\core\handlers\base.py", line 158, in get_response
    % (callback.__module__, view_name))
ValueError: The view app.director_views.director_add_panel_members didn't return an HttpResponse object. It returned None instead.
2017-04-19 21:04:01 - ERROR - base:handle_uncaught_exception:284 - Internal Server Error: /director/panel/add/
Traceback (most recent call last):
  File "E:\Education\GitHub Projects\PhDPortal\env\lib\site-packages\django\core\handlers\base.py", line 158, in get_response
    % (callback.__module__, view_name))
ValueError: The view app.director_views.director_add_panel_members didn't return an HttpResponse object. It returned None instead.
2017-04-19 21:04:25 - ERROR - base:handle_uncaught_exception:284 - Internal Server Error: /director/panel/add/
Traceback (most recent call last):
  File "E:\Education\GitHub Projects\PhDPortal\env\lib\site-packages\django\core\handlers\base.py", line 158, in get_response
    % (callback.__module__, view_name))
ValueError: The view app.director_views.director_add_panel_members didn't return an HttpResponse object. It returned None instead.
2017-04-19 21:05:19 - ERROR - base:handle_uncaught_exception:284 - Internal Server Error: /director/panel/add/
Traceback (most recent call last):
  File "E:\Education\GitHub Projects\PhDPortal\env\lib\site-packages\django\core\handlers\base.py", line 158, in get_response
    % (callback.__module__, view_name))
ValueError: The view app.director_views.director_add_panel_members didn't return an HttpResponse object. It returned None instead.
